Workbook

Sheet Invoice Template
K1: This is X spend (Aleph to invoice the clients) - Cost to pay X in column CS | CS1: Cost to pay the partner
L5: IO Attributes | S5: Local Gross Revenue (Net of LOI) | Y5: Local Direct Tax | AE5: Local Commission | AK5: Local Withholding Tax | AQ5: Local Regulatory Complexity Fee | AW5: Local Currency Complexity Fee | BC5: Local Total Commission and Tax | BI5: Entered Currency Direct Tax | BO5: Entered Currency Commission | BU5: Entered Currency Withholding Tax | CA5: Entered Currency Regulatory Complexity Fee | CG5: Entered Currency Currency Complexity Fee | CM5: Entered Currency Total Commission and Tax | CS5: Entered Currency | DF5: Update from Monthly FX File as of Jan'26(Corp.rate)
A6: Campaign ID | B6: IO# | C6: Salesforce IO ID | D6: Currency | E6: Amplify Sponsorship | F6: Twitter Takeover | G6: Promoted Ads | H6: Twitter Publisher Network | I6: Amplify Instream Pre-Roll | J6: Commission Rate | K6: Revenue Net of LOI | L6: Currency | M6: IO FX Rate | N6: Country Billed from | O6: Direct Tax Rate | P6: W/H Tax rate | Q6: Regulatory Complexity Fee | R6: Currency Complexity Fee | S6: Local PAc | T6: Local PTr | U6: Local PTw | V6: Local TPN | W6: Local Amplify | X6: Local Gross Revenue (Net of LOI) Total | Y6: Local PAc Direct Tax | Z6: Local PTr Direct Tax | AA6: Local PTw Direct Tax | AB6: Local TPN Direct Tax | AC6: Local Amplify Direct Tax | AD6: Local Direct Tax Total | AE6: Local PAc Commission | AF6: Local PTr Commission | AG6: Local PTw Commission | AH6: Local TPN Commission | AI6: Local Amplify Commission | AJ6: Local Commission Total | AK6: Local PAc W/H Tax | AL6: Local PTr W/H Tax | AM6: Local PTw W/H Tax | AN6: Local TPN W/H Tax | AO6: Local Amplify W/H Tax | AP6: Local Withholding Tax Total | AQ6: Local PAc Reg Fee | AR6: Local PTr Reg Fee | AS6: Local PTw Reg Fee | AT6: Local TPN Reg Fee | AU6: Local Amplify Reg Fee | AV6: Local Reg Fee Total | AW6: Local PAc Curr. Complex Fee | AX6: Local PTr Curr. Complex Fee | AY6: Local PTw Curr. Complex Fee | AZ6: Local TPN Curr. Complex Fee | BA6: Local Amplify Curr. Complex Fee | BB6: Local Curr. Complex Fee Total | BC6: Local PAc Total | BD6: Local PTr Total | BE6: Local PTw Total | BF6: Local TPN Total | BG6: Local Amplify Total | BH6: Local Total Comm & Tax | BI6: PAc Total | BJ6: PTr Total | BK6: PTw Total | BL6: TPN Total | BM6: Amplify Total | BN6: Direct Tax Total | BO6: PAc Total | BP6: PTr Total | BQ6: PTw Total | BR6: TPN Total | BS6: Amplify Total | BT6: Commission Total | BU6: PAc Total | BV6: PTr Total | BW6: PTw Total | BX6: TPN Total | BY6: Amplify Total | BZ6: Withholding Tax Total | CA6: PAc Total | CB6: PTr Total | CC6: PTw Total | CD6: TPN Total | CE6: Amplify Total | CF6: Regulatory Complexity Fee Total | CG6: PAc Total | CH6: PTr Total | CI6: PTw Total | CJ6: TPN Total | CK6: Amplify Total | CL6: Currency Complexity Fee Total | CM6: PAc Consol Total | CN6: PTr Consol Total | CO6: PTw Consol Total | CP6: TPN Consol Total | CQ6: Amplify Consol Total | CR6: Consol Total Comm & Tax | CS6: Total Invoiced amount | CT6: Comments for 0% Direct tax | CU6: Billed Currency | CV6: FX Rate to USD | CW6: USD Revenue Net of LOI | CX6: USD Total Direct Tax | CY6: USD Total Commission | CZ6: USD Total W/H Tax | DA6: USD Total Regulatory Complexity Fee | DB6: USD Total Currency Complexity Fee | DC6: USD Total Invoiced Amt | DD6: Campaign Name | DF6: Billed Currency | DG6: Fx Rate to USD
A7: 40459084 | B7: T2694837 | C7: 269483701 | D7: ARS | G7: 911867.62 | J7: =VLOOKUP($B7,'IMS Commission List'!E:CE,79,0)/100 -> 0.15 | K7: =SUM(E7:I7) -> 911867.62 | L7: =VLOOKUP($B7,'IMS Commission List'!E:V,18,0) -> ARS | M7: 1 | N7: =VLOOKUP($B7,'IMS Commission List'!E:T,16,0) -> MX | O7: =VLOOKUP($B7,'IMS Commission List'!E:CF,80,0) -> 0.049 | P7: =VLOOKUP($B7,'IMS Commission List'!E:CG,81,0) -> 0.1575 | Q7: =VLOOKUP($B7,'IMS Commission List'!E:CP,90,0) -> 0.03 | R7: =VLOOKUP($B7,'IMS Commission List'!E:CQ,91,0) -> 0.04 | S7: =$E7*$M7 -> 0 | T7: =$F7*$M7 -> 0 | U7: =$G7*$M7 -> 911867.62 | V7: =$H7*$M7 -> 0 | W7: =$I7*$M7 -> 0 | X7: =$K7*$M7 -> 911867.62 | Y7: =(S7*$O7)*(1-J7) -> 0 | Z7: =(T7*$O7)*(1-J7) -> 0 | AA7: =(U7*$O7)*(1-J7) -> 37979.286 | AB7: =(V7*$O7)*(1-J7) -> 0 | AC7: =(W7*$O7)*(1-J7) -> 0 | AD7: =SUM(Y7:AC7) -> 37979.286 | AE7: =S7*$J7 -> 0 | AF7: =T7*$J7 -> 0 | AG7: =U7*$J7 -> 136780.14 | AH7: =V7*$J7 -> 0 | AI7: =W7*$J7 -> 0 | AJ7: =SUM(AE7:AI7) -> 136780.14 | AK7: =($P7*S7)*(1-$J7) -> 0 | AL7: =($P7*T7)*(1-$J7) -> 0 | AM7: =($P7*U7)*(1-$J7) -> 122076.28 | AN7: =($P7*V7)*(1-$J7) -> 0 | AO7: =($P7*W7)*(1-$J7) -> 0 | AP7: =SUM(AK7:AO7) -> 122076.28 | AQ7: =S7*$Q7 -> 0 | AR7: =T7*$Q7 -> 0 | AS7: =U7*$Q7 -> 27356.029 | AT7: =V7*$Q7 -> 0 | AU7: =W7*$Q7 -> 0 | AV7: =SUM(AQ7:AU7) -> 27356.029 | AW7: =S7*$R7 -> 0 | AX7: =T7*$R7 -> 0 | AY7: =U7*$R7 -> 36474.705 | AZ7: =V7*$R7 -> 0 | BA7: =W7*$R7 -> 0 | BB7: =SUM(AW7:BA7) -> 36474.705 | BC7: =$Y7+$AE7+$AK7+$AQ7+AW7 -> 0 | BD7: =$Z7+$AF7+$AL7+AR7+AX7 -> 0 | BE7: =$AA7+$AG7+$AM7+AS7+AY7 -> 360666.44 | BF7: =$AB7+$AH7+$AN7+AT7+AZ7 -> 0 | BG7: =$AC7+$AI7+$AO7+AU7+BA7 -> 0 | BH7: =SUM(BC7:BG7) -> 360666.44 | BI7: =$Y7/$M7 -> 0 | BJ7: =$Z7/$M7 -> 0 | BK7: =$AA7/$M7 -> 37979.286 | BL7: =$AB7/$M7 -> 0 | BM7: =$AC7/$M7 -> 0 | BN7: =$AD7/$M7 -> 37979.286 | BO7: =$AE7/$M7 -> 0 | BP7: =$AF7/$M7 -> 0 | BQ7: =$AG7/$M7 -> 136780.14 | BR7: =$AH7/$M7 -> 0 | BS7: =$AI7/$M7 -> 0 | BT7: =$AJ7/$M7 -> 136780.14 | BU7: =$AK7/$M7 -> 0 | BV7: =$AL7/$M7 -> 0 | BW7: =$AM7/$M7 -> 122076.28 | BX7: =$AN7/$M7 -> 0 | BY7: =$AO7/$M7 -> 0 | BZ7: =$AP7/$M7 -> 122076.28 | CA7: =AQ7/$M7 -> 0 | CB7: =AR7/$M7 -> 0 | CC7: =AS7/$M7 -> 27356.029 | CD7: =AT7/$M7 -> 0 | CE7: =AU7/$M7 -> 0 | CF7: =AV7/$M7 -> 27356.029 | CG7: =AW7/$M7 -> 0 | CH7: =AX7/$M7 -> 0 | ... CL7: =BB7/$M7 -> 36474.705 | CM7: =$BC7/$M7 -> 0 | CN7: =$BD7/$M7 -> 0 | CO7: =$BE7/$M7 -> 360666.44 | CP7: =$BF7/$M7 -> 0 | CQ7: =$BG7/$M7 -> 0 | CR7: =SUM(CM7:CQ7) -> 360666.44 | CS7: =K7-CR7 -> 551201.18 | CU7: =D7 -> ARS | CV7: =VLOOKUP(CU7,DF:DG,2,0) -> 0.0006918517 | CW7: =K7*CV7 -> 630.87716 | CX7: =BN7*CV7 -> 26.276034 | CY7: =BT7*CV7 -> 94.631574 | CZ7: =BZ7*CV7 -> 84.45868 | DA7: =CF7*CV7 -> 18.926315 | DB7: =CL7*CV7 -> 25.235087 | DC7: =CS7*CV7 -> 381.34947 | DD7: =VLOOKUP(A7,'Billing Report'!H:I,2,FALSE) -> BULL_LEMON_AR_INTERACCION_TW_ALL_BROAD_AO_NEW | DF7: AED | DG7: 0.27227703
A8: 40931692 | B8: T2751490 | C8: 275149001 | D8: ARS | G8: 900539.44 | J8: =VLOOKUP($B8,'IMS Commission List'!E:CE,79,0)/100 -> 0.15 | K8: =SUM(E8:I8) -> 900539.44 | L8: =VLOOKUP($B8,'IMS Commission List'!E:V,18,0) -> ARS | M8: 1 | N8: =VLOOKUP($B8,'IMS Commission List'!E:T,16,0) -> MX | O8: =VLOOKUP($B8,'IMS Commission List'!E:CF,80,0) -> 0.049 | P8: =VLOOKUP($B8,'IMS Commission List'!E:CG,81,0) -> 0.1575 | Q8: =VLOOKUP($B8,'IMS Commission List'!E:CP,90,0) -> 0.03 | R8: =VLOOKUP($B8,'IMS Commission List'!E:CQ,91,0) -> 0.04 | S8: =$E8*$M8 -> 0 | T8: =$F8*$M8 -> 0 | U8: =$G8*$M8 -> 900539.44 | V8: =$H8*$M8 -> 0 | W8: =$I8*$M8 -> 0 | X8: =$K8*$M8 -> 900539.44 | Y8: =(S8*$O8)*(1-J8) -> 0 | Z8: =(T8*$O8)*(1-J8) -> 0 | AA8: =(U8*$O8)*(1-J8) -> 37507.468 | AB8: =(V8*$O8)*(1-J8) -> 0 | AC8: =(W8*$O8)*(1-J8) -> 0 | AD8: =SUM(Y8:AC8) -> 37507.468 | AE8: =S8*$J8 -> 0 | AF8: =T8*$J8 -> 0 | AG8: =U8*$J8 -> 135080.92 | AH8: =V8*$J8 -> 0 | AI8: =W8*$J8 -> 0 | AJ8: =SUM(AE8:AI8) -> 135080.92 | AK8: =($P8*S8)*(1-$J8) -> 0 | AL8: =($P8*T8)*(1-$J8) -> 0 | AM8: =($P8*U8)*(1-$J8) -> 120559.72 | AN8: =($P8*V8)*(1-$J8) -> 0 | AO8: =($P8*W8)*(1-$J8) -> 0 | AP8: =SUM(AK8:AO8) -> 120559.72 | AQ8: =S8*$Q8 -> 0 | AR8: =T8*$Q8 -> 0 | AS8: =U8*$Q8 -> 27016.183 | AT8: =V8*$Q8 -> 0 | AU8: =W8*$Q8 -> 0 | AV8: =SUM(AQ8:AU8) -> 27016.183 | AW8: =S8*$R8 -> 0 | AX8: =T8*$R8 -> 0 | AY8: =U8*$R8 -> 36021.578 | AZ8: =V8*$R8 -> 0 | BA8: =W8*$R8 -> 0 | BB8: =SUM(AW8:BA8) -> 36021.578 | BC8: =$Y8+$AE8+$AK8+$AQ8+AW8 -> 0 | BD8: =$Z8+$AF8+$AL8+AR8+AX8 -> 0 | BE8: =$AA8+$AG8+$AM8+AS8+AY8 -> 356185.86 | BF8: =$AB8+$AH8+$AN8+AT8+AZ8 -> 0 | BG8: =$AC8+$AI8+$AO8+AU8+BA8 -> 0 | BH8: =SUM(BC8:BG8) -> 356185.86 | BI8: =$Y8/$M8 -> 0 | BJ8: =$Z8/$M8 -> 0 | BK8: =$AA8/$M8 -> 37507.468 | BL8: =$AB8/$M8 -> 0 | BM8: =$AC8/$M8 -> 0 | BN8: =$AD8/$M8 -> 37507.468 | BO8: =$AE8/$M8 -> 0 | BP8: =$AF8/$M8 -> 0 | BQ8: =$AG8/$M8 -> 135080.92 | BR8: =$AH8/$M8 -> 0 | BS8: =$AI8/$M8 -> 0 | BT8: =$AJ8/$M8 -> 135080.92 | BU8: =$AK8/$M8 -> 0 | BV8: =$AL8/$M8 -> 0 | BW8: =$AM8/$M8 -> 120559.72 | BX8: =$AN8/$M8 -> 0 | BY8: =$AO8/$M8 -> 0 | BZ8: =$AP8/$M8 -> 120559.72 | CA8: =AQ8/$M8 -> 0 | CB8: =AR8/$M8 -> 0 | CC8: =AS8/$M8 -> 27016.183 | CD8: =AT8/$M8 -> 0 | CE8: =AU8/$M8 -> 0 | CF8: =AV8/$M8 -> 27016.183 | CG8: =AW8/$M8 -> 0 | CH8: =AX8/$M8 -> 0 | ... CL8: =BB8/$M8 -> 36021.578 | CM8: =$BC8/$M8 -> 0 | CN8: =$BD8/$M8 -> 0 | CO8: =$BE8/$M8 -> 356185.86 | CP8: =$BF8/$M8 -> 0 | CQ8: =$BG8/$M8 -> 0 | CR8: =SUM(CM8:CQ8) -> 356185.86 | CS8: =K8-CR8 -> 544353.58 | CU8: =D8 -> ARS | CV8: =VLOOKUP(CU8,DF:DG,2,0) -> 0.0006918517 | CW8: =K8*CV8 -> 623.03974 | CX8: =BN8*CV8 -> 25.949605 | CY8: =BT8*CV8 -> 93.455961 | CZ8: =BZ8*CV8 -> 83.409446 | DA8: =CF8*CV8 -> 18.691192 | DB8: =CL8*CV8 -> 24.92159 | DC8: =CS8*CV8 -> 376.61195 | DD8: =VLOOKUP(A8,'Billing Report'!H:I,2,FALSE) -> OT467 Vuelta al cole - Alcance - TWITTER | DF8: ALL | DG8: 0.012329646
A9: 40888664 | B9: T2751490 | C9: 275149001 | D9: ARS | G9: 162996.65 | J9: =VLOOKUP($B9,'IMS Commission List'!E:CE,79,0)/100 -> 0.15 | K9: =SUM(E9:I9) -> 162996.65 | L9: =VLOOKUP($B9,'IMS Commission List'!E:V,18,0) -> ARS | M9: 1 | N9: =VLOOKUP($B9,'IMS Commission List'!E:T,16,0) -> MX | O9: =VLOOKUP($B9,'IMS Commission List'!E:CF,80,0) -> 0.049 | P9: =VLOOKUP($B9,'IMS Commission List'!E:CG,81,0) -> 0.1575 | Q9: =VLOOKUP($B9,'IMS Commission List'!E:CP,90,0) -> 0.03 | R9: =VLOOKUP($B9,'IMS Commission List'!E:CQ,91,0) -> 0.04 | S9: =$E9*$M9 -> 0 | T9: =$F9*$M9 -> 0 | U9: =$G9*$M9 -> 162996.65 | V9: =$H9*$M9 -> 0 | W9: =$I9*$M9 -> 0 | X9: =$K9*$M9 -> 162996.65 | Y9: =(S9*$O9)*(1-J9) -> 0 | Z9: =(T9*$O9)*(1-J9) -> 0 | AA9: =(U9*$O9)*(1-J9) -> 6788.8105 | AB9: =(V9*$O9)*(1-J9) -> 0 | AC9: =(W9*$O9)*(1-J9) -> 0 | AD9: =SUM(Y9:AC9) -> 6788.8105 | AE9: =S9*$J9 -> 0 | AF9: =T9*$J9 -> 0 | AG9: =U9*$J9 -> 24449.498 | AH9: =V9*$J9 -> 0 | AI9: =W9*$J9 -> 0 | AJ9: =SUM(AE9:AI9) -> 24449.498 | AK9: =($P9*S9)*(1-$J9) -> 0 | AL9: =($P9*T9)*(1-$J9) -> 0 | AM9: =($P9*U9)*(1-$J9) -> 21821.177 | AN9: =($P9*V9)*(1-$J9) -> 0 | AO9: =($P9*W9)*(1-$J9) -> 0 | AP9: =SUM(AK9:AO9) -> 21821.177 | AQ9: =S9*$Q9 -> 0 | AR9: =T9*$Q9 -> 0 | AS9: =U9*$Q9 -> 4889.8995 | AT9: =V9*$Q9 -> 0 | AU9: =W9*$Q9 -> 0 | AV9: =SUM(AQ9:AU9) -> 4889.8995 | AW9: =S9*$R9 -> 0 | AX9: =T9*$R9 -> 0 | AY9: =U9*$R9 -> 6519.866 | AZ9: =V9*$R9 -> 0 | BA9: =W9*$R9 -> 0 | BB9: =SUM(AW9:BA9) -> 6519.866 | BC9: =$Y9+$AE9+$AK9+$AQ9+AW9 -> 0 | BD9: =$Z9+$AF9+$AL9+AR9+AX9 -> 0 | BE9: =$AA9+$AG9+$AM9+AS9+AY9 -> 64469.25 | BF9: =$AB9+$AH9+$AN9+AT9+AZ9 -> 0 | BG9: =$AC9+$AI9+$AO9+AU9+BA9 -> 0 | BH9: =SUM(BC9:BG9) -> 64469.25 | BI9: =$Y9/$M9 -> 0 | BJ9: =$Z9/$M9 -> 0 | BK9: =$AA9/$M9 -> 6788.8105 | BL9: =$AB9/$M9 -> 0 | BM9: =$AC9/$M9 -> 0 | BN9: =$AD9/$M9 -> 6788.8105 | BO9: =$AE9/$M9 -> 0 | BP9: =$AF9/$M9 -> 0 | BQ9: =$AG9/$M9 -> 24449.498 | BR9: =$AH9/$M9 -> 0 | BS9: =$AI9/$M9 -> 0 | BT9: =$AJ9/$M9 -> 24449.498 | BU9: =$AK9/$M9 -> 0 | BV9: =$AL9/$M9 -> 0 | BW9: =$AM9/$M9 -> 21821.177 | BX9: =$AN9/$M9 -> 0 | BY9: =$AO9/$M9 -> 0 | BZ9: =$AP9/$M9 -> 21821.177 | CA9: =AQ9/$M9 -> 0 | CB9: =AR9/$M9 -> 0 | CC9: =AS9/$M9 -> 4889.8995 | CD9: =AT9/$M9 -> 0 | CE9: =AU9/$M9 -> 0 | CF9: =AV9/$M9 -> 4889.8995 | CG9: =AW9/$M9 -> 0 | CH9: =AX9/$M9 -> 0 | ... CL9: =BB9/$M9 -> 6519.866 | CM9: =$BC9/$M9 -> 0 | CN9: =$BD9/$M9 -> 0 | CO9: =$BE9/$M9 -> 64469.25 | CP9: =$BF9/$M9 -> 0 | CQ9: =$BG9/$M9 -> 0 | CR9: =SUM(CM9:CQ9) -> 64469.25 | CS9: =K9-CR9 -> 98527.4 | CU9: =D9 -> ARS | CV9: =VLOOKUP(CU9,DF:DG,2,0) -> 0.0006918517 | CW9: =K9*CV9 -> 112.76951 | CX9: =BN9*CV9 -> 4.6968501 | CY9: =BT9*CV9 -> 16.915426 | CZ9: =BZ9*CV9 -> 15.097018 | DA9: =CF9*CV9 -> 3.3830853 | DB9: =CL9*CV9 -> 4.5107804 | DC9: =CS9*CV9 -> 68.166349 | DD9: =VLOOKUP(A9,'Billing Report'!H:I,2,FALSE) -> OT470 Inversiones Feb26 - Tráfico - TWITTER | DF9: ARS | DG9: 0.0006918517
A10: 40888662 | B10: T2751490 | C10: 275149001 | D10: ARS | G10: 102565.52 | J10: =VLOOKUP($B10,'IMS Commission List'!E:CE,79,0)/100 -> 0.15 | K10: =SUM(E10:I10) -> 102565.52 | L10: =VLOOKUP($B10,'IMS Commission List'!E:V,18,0) -> ARS | M10: 1 | N10: =VLOOKUP($B10,'IMS Commission List'!E:T,16,0) -> MX | O10: =VLOOKUP($B10,'IMS Commission List'!E:CF,80,0) -> 0.049 | P10: =VLOOKUP($B10,'IMS Commission List'!E:CG,81,0) -> 0.1575 | Q10: =VLOOKUP($B10,'IMS Commission List'!E:CP,90,0) -> 0.03 | R10: =VLOOKUP($B10,'IMS Commission List'!E:CQ,91,0) -> 0.04 | S10: =$E10*$M10 -> 0 | T10: =$F10*$M10 -> 0 | U10: =$G10*$M10 -> 102565.52 | V10: =$H10*$M10 -> 0 | W10: =$I10*$M10 -> 0 | X10: =$K10*$M10 -> 102565.52 | Y10: =(S10*$O10)*(1-J10) -> 0 | Z10: =(T10*$O10)*(1-J10) -> 0 | AA10: =(U10*$O10)*(1-J10) -> 4271.8539 | AB10: =(V10*$O10)*(1-J10) -> 0 | AC10: =(W10*$O10)*(1-J10) -> 0 | AD10: =SUM(Y10:AC10) -> 4271.8539 | AE10: =S10*$J10 -> 0 | AF10: =T10*$J10 -> 0 | AG10: =U10*$J10 -> 15384.828 | AH10: =V10*$J10 -> 0 | AI10: =W10*$J10 -> 0 | AJ10: =SUM(AE10:AI10) -> 15384.828 | AK10: =($P10*S10)*(1-$J10) -> 0 | AL10: =($P10*T10)*(1-$J10) -> 0 | AM10: =($P10*U10)*(1-$J10) -> 13730.959 | AN10: =($P10*V10)*(1-$J10) -> 0 | AO10: =($P10*W10)*(1-$J10) -> 0 | AP10: =SUM(AK10:AO10) -> 13730.959 | AQ10: =S10*$Q10 -> 0 | AR10: =T10*$Q10 -> 0 | AS10: =U10*$Q10 -> 3076.9656 | AT10: =V10*$Q10 -> 0 | AU10: =W10*$Q10 -> 0 | AV10: =SUM(AQ10:AU10) -> 3076.9656 | AW10: =S10*$R10 -> 0 | AX10: =T10*$R10 -> 0 | AY10: =U10*$R10 -> 4102.6208 | AZ10: =V10*$R10 -> 0 | BA10: =W10*$R10 -> 0 | BB10: =SUM(AW10:BA10) -> 4102.6208 | BC10: =$Y10+$AE10+$AK10+$AQ10+AW10 -> 0 | BD10: =$Z10+$AF10+$AL10+AR10+AX10 -> 0 | BE10: =$AA10+$AG10+$AM10+AS10+AY10 -> 40567.227 | BF10: =$AB10+$AH10+$AN10+AT10+AZ10 -> 0 | BG10: =$AC10+$AI10+$AO10+AU10+BA10 -> 0 | BH10: =SUM(BC10:BG10) -> 40567.227 | BI10: =$Y10/$M10 -> 0 | BJ10: =$Z10/$M10 -> 0 | BK10: =$AA10/$M10 -> 4271.8539 | BL10: =$AB10/$M10 -> 0 | BM10: =$AC10/$M10 -> 0 | BN10: =$AD10/$M10 -> 4271.8539 | BO10: =$AE10/$M10 -> 0 | BP10: =$AF10/$M10 -> 0 | BQ10: =$AG10/$M10 -> 15384.828 | BR10: =$AH10/$M10 -> 0 | BS10: =$AI10/$M10 -> 0 | BT10: =$AJ10/$M10 -> 15384.828 | BU10: =$AK10/$M10 -> 0 | BV10: =$AL10/$M10 -> 0 | BW10: =$AM10/$M10 -> 13730.959 | BX10: =$AN10/$M10 -> 0 | BY10: =$AO10/$M10 -> 0 | BZ10: =$AP10/$M10 -> 13730.959 | CA10: =AQ10/$M10 -> 0 | CB10: =AR10/$M10 -> 0 | CC10: =AS10/$M10 -> 3076.9656 | CD10: =AT10/$M10 -> 0 | CE10: =AU10/$M10 -> 0 | CF10: =AV10/$M10 -> 3076.9656 | CG10: =AW10/$M10 -> 0 | CH10: =AX10/$M10 -> 0 | ... CL10: =BB10/$M10 -> 4102.6208 | CM10: =$BC10/$M10 -> 0 | CN10: =$BD10/$M10 -> 0 | CO10: =$BE10/$M10 -> 40567.227 | CP10: =$BF10/$M10 -> 0 | CQ10: =$BG10/$M10 -> 0 | CR10: =SUM(CM10:CQ10) -> 40567.227 | CS10: =K10-CR10 -> 61998.293 | CU10: =D10 -> ARS | CV10: =VLOOKUP(CU10,DF:DG,2,0) -> 0.0006918517 | CW10: =K10*CV10 -> 70.960129 | CX10: =BN10*CV10 -> 2.9554894 | CY10: =BT10*CV10 -> 10.644019 | CZ10: =BZ10*CV10 -> 9.4997873 | DA10: =CF10*CV10 -> 2.1288039 | DB10: =CL10*CV10 -> 2.8384052 | DC10: =CS10*CV10 -> 42.893624 | DD10: =VLOOKUP(A10,'Billing Report'!H:I,2,FALSE) -> OT470 Inversiones Feb26 - Alcance - TWITTER | DF10: AUD | DG10: 0.69938873
A11: 40888605 | B11: T2751490 | C11: 275149001 | D11: ARS | G11: 413581.86 | J11: =VLOOKUP($B11,'IMS Commission List'!E:CE,79,0)/100 -> 0.15 | K11: =SUM(E11:I11) -> 413581.86 | L11: =VLOOKUP($B11,'IMS Commission List'!E:V,18,0) -> ARS | M11: 1 | N11: =VLOOKUP($B11,'IMS Commission List'!E:T,16,0) -> MX | O11: =VLOOKUP($B11,'IMS Commission List'!E:CF,80,0) -> 0.049 | P11: =VLOOKUP($B11,'IMS Commission List'!E:CG,81,0) -> 0.1575 | Q11: =VLOOKUP($B11,'IMS Commission List'!E:CP,90,0) -> 0.03 | R11: =VLOOKUP($B11,'IMS Commission List'!E:CQ,91,0) -> 0.04 | S11: =$E11*$M11 -> 0 | T11: =$F11*$M11 -> 0 | U11: =$G11*$M11 -> 413581.86 | V11: =$H11*$M11 -> 0 | W11: =$I11*$M11 -> 0 | X11: =$K11*$M11 -> 413581.86 | Y11: =(S11*$O11)*(1-J11) -> 0 | Z11: =(T11*$O11)*(1-J11) -> 0 | AA11: =(U11*$O11)*(1-J11) -> 17225.684 | AB11: =(V11*$O11)*(1-J11) -> 0 | AC11: =(W11*$O11)*(1-J11) -> 0 | AD11: =SUM(Y11:AC11) -> 17225.684 | AE11: =S11*$J11 -> 0 | AF11: =T11*$J11 -> 0 | AG11: =U11*$J11 -> 62037.279 | AH11: =V11*$J11 -> 0 | AI11: =W11*$J11 -> 0 | AJ11: =SUM(AE11:AI11) -> 62037.279 | AK11: =($P11*S11)*(1-$J11) -> 0 | AL11: =($P11*T11)*(1-$J11) -> 0 | AM11: =($P11*U11)*(1-$J11) -> 55368.272 | AN11: =($P11*V11)*(1-$J11) -> 0 | AO11: =($P11*W11)*(1-$J11) -> 0 | AP11: =SUM(AK11:AO11) -> 55368.272 | AQ11: =S11*$Q11 -> 0 | AR11: =T11*$Q11 -> 0 | AS11: =U11*$Q11 -> 12407.456 | AT11: =V11*$Q11 -> 0 | AU11: =W11*$Q11 -> 0 | AV11: =SUM(AQ11:AU11) -> 12407.456 | AW11: =S11*$R11 -> 0 | AX11: =T11*$R11 -> 0 | AY11: =U11*$R11 -> 16543.274 | AZ11: =V11*$R11 -> 0 | BA11: =W11*$R11 -> 0 | BB11: =SUM(AW11:BA11) -> 16543.274 | BC11: =$Y11+$AE11+$AK11+$AQ11+AW11 -> 0 | BD11: =$Z11+$AF11+$AL11+AR11+AX11 -> 0 | BE11: =$AA11+$AG11+$AM11+AS11+AY11 -> 163581.97 | BF11: =$AB11+$AH11+$AN11+AT11+AZ11 -> 0 | BG11: =$AC11+$AI11+$AO11+AU11+BA11 -> 0 | BH11: =SUM(BC11:BG11) -> 163581.97 | BI11: =$Y11/$M11 -> 0 | BJ11: =$Z11/$M11 -> 0 | BK11: =$AA11/$M11 -> 17225.684 | BL11: =$AB11/$M11 -> 0 | BM11: =$AC11/$M11 -> 0 | BN11: =$AD11/$M11 -> 17225.684 | BO11: =$AE11/$M11 -> 0 | BP11: =$AF11/$M11 -> 0 | BQ11: =$AG11/$M11 -> 62037.279 | BR11: =$AH11/$M11 -> 0 | BS11: =$AI11/$M11 -> 0 | BT11: =$AJ11/$M11 -> 62037.279 | BU11: =$AK11/$M11 -> 0 | BV11: =$AL11/$M11 -> 0 | BW11: =$AM11/$M11 -> 55368.272 | BX11: =$AN11/$M11 -> 0 | BY11: =$AO11/$M11 -> 0 | BZ11: =$AP11/$M11 -> 55368.272 | CA11: =AQ11/$M11 -> 0 | CB11: =AR11/$M11 -> 0 | CC11: =AS11/$M11 -> 12407.456 | CD11: =AT11/$M11 -> 0 | CE11: =AU11/$M11 -> 0 | CF11: =AV11/$M11 -> 12407.456 | CG11: =AW11/$M11 -> 0 | CH11: =AX11/$M11 -> 0 | ... CL11: =BB11/$M11 -> 16543.274 | CM11: =$BC11/$M11 -> 0 | CN11: =$BD11/$M11 -> 0 | CO11: =$BE11/$M11 -> 163581.97 | CP11: =$BF11/$M11 -> 0 | CQ11: =$BG11/$M11 -> 0 | CR11: =SUM(CM11:CQ11) -> 163581.97 | CS11: =K11-CR11 -> 249999.89 | CU11: =D11 -> ARS | CV11: =VLOOKUP(CU11,DF:DG,2,0) -> 0.0006918517 | CW11: =K11*CV11 -> 286.13731 | CX11: =BN11*CV11 -> 11.917619 | CY11: =BT11*CV11 -> 42.920597 | CZ11: =BZ11*CV11 -> 38.306633 | DA11: =CF11*CV11 -> 8.5841194 | DB11: =CL11*CV11 -> 11.445493 | DC11: =CS11*CV11 -> 172.96285 | DD11: =VLOOKUP(A11,'Billing Report'!H:I,2,FALSE) -> OT473 Ciberdelito Feb26 - Alcance - TWITTER | DF11: BAM | DG11: 0.60864087
A12: 40855406 | B12: T2751490 | C12: 275149001 | D12: ARS | G12: 1389582.7 | J12: =VLOOKUP($B12,'IMS Commission List'!E:CE,79,0)/100 -> 0.15 | K12: =SUM(E12:I12) -> 1389582.7 | L12: =VLOOKUP($B12,'IMS Commission List'!E:V,18,0) -> ARS | M12: 1 | N12: =VLOOKUP($B12,'IMS Commission List'!E:T,16,0) -> MX | O12: =VLOOKUP($B12,'IMS Commission List'!E:CF,80,0) -> 0.049 | P12: =VLOOKUP($B12,'IMS Commission List'!E:CG,81,0) -> 0.1575 | Q12: =VLOOKUP($B12,'IMS Commission List'!E:CP,90,0) -> 0.03 | R12: =VLOOKUP($B12,'IMS Commission List'!E:CQ,91,0) -> 0.04 | S12: =$E12*$M12 -> 0 | T12: =$F12*$M12 -> 0 | U12: =$G12*$M12 -> 1389582.7 | V12: =$H12*$M12 -> 0 | W12: =$I12*$M12 -> 0 | X12: =$K12*$M12 -> 1389582.7 | Y12: =(S12*$O12)*(1-J12) -> 0 | Z12: =(T12*$O12)*(1-J12) -> 0 | AA12: =(U12*$O12)*(1-J12) -> 57876.117 | AB12: =(V12*$O12)*(1-J12) -> 0 | AC12: =(W12*$O12)*(1-J12) -> 0 | AD12: =SUM(Y12:AC12) -> 57876.117 | AE12: =S12*$J12 -> 0 | AF12: =T12*$J12 -> 0 | AG12: =U12*$J12 -> 208437.4 | AH12: =V12*$J12 -> 0 | AI12: =W12*$J12 -> 0 | AJ12: =SUM(AE12:AI12) -> 208437.4 | AK12: =($P12*S12)*(1-$J12) -> 0 | AL12: =($P12*T12)*(1-$J12) -> 0 | AM12: =($P12*U12)*(1-$J12) -> 186030.38 | AN12: =($P12*V12)*(1-$J12) -> 0 | AO12: =($P12*W12)*(1-$J12) -> 0 | AP12: =SUM(AK12:AO12) -> 186030.38 | AQ12: =S12*$Q12 -> 0 | AR12: =T12*$Q12 -> 0 | AS12: =U12*$Q12 -> 41687.48 | AT12: =V12*$Q12 -> 0 | AU12: =W12*$Q12 -> 0 | AV12: =SUM(AQ12:AU12) -> 41687.48 | AW12: =S12*$R12 -> 0 | AX12: =T12*$R12 -> 0 | AY12: =U12*$R12 -> 55583.306 | AZ12: =V12*$R12 -> 0 | BA12: =W12*$R12 -> 0 | BB12: =SUM(AW12:BA12) -> 55583.306 | BC12: =$Y12+$AE12+$AK12+$AQ12+AW12 -> 0 | BD12: =$Z12+$AF12+$AL12+AR12+AX12 -> 0 | BE12: =$AA12+$AG12+$AM12+AS12+AY12 -> 549614.68 | BF12: =$AB12+$AH12+$AN12+AT12+AZ12 -> 0 | BG12: =$AC12+$AI12+$AO12+AU12+BA12 -> 0 | BH12: =SUM(BC12:BG12) -> 549614.68 | BI12: =$Y12/$M12 -> 0 | BJ12: =$Z12/$M12 -> 0 | BK12: =$AA12/$M12 -> 57876.117 | BL12: =$AB12/$M12 -> 0 | BM12: =$AC12/$M12 -> 0 | BN12: =$AD12/$M12 -> 57876.117 | BO12: =$AE12/$M12 -> 0 | BP12: =$AF12/$M12 -> 0 | BQ12: =$AG12/$M12 -> 208437.4 | BR12: =$AH12/$M12 -> 0 | BS12: =$AI12/$M12 -> 0 | BT12: =$AJ12/$M12 -> 208437.4 | BU12: =$AK12/$M12 -> 0 | BV12: =$AL12/$M12 -> 0 | BW12: =$AM12/$M12 -> 186030.38 | BX12: =$AN12/$M12 -> 0 | BY12: =$AO12/$M12 -> 0 | BZ12: =$AP12/$M12 -> 186030.38 | CA12: =AQ12/$M12 -> 0 | CB12: =AR12/$M12 -> 0 | CC12: =AS12/$M12 -> 41687.48 | CD12: =AT12/$M12 -> 0 | CE12: =AU12/$M12 -> 0 | CF12: =AV12/$M12 -> 41687.48 | CG12: =AW12/$M12 -> 0 | CH12: =AX12/$M12 -> 0 | ... CL12: =BB12/$M12 -> 55583.306 | CM12: =$BC12/$M12 -> 0 | CN12: =$BD12/$M12 -> 0 | CO12: =$BE12/$M12 -> 549614.68 | CP12: =$BF12/$M12 -> 0 | CQ12: =$BG12/$M12 -> 0 | CR12: =SUM(CM12:CQ12) -> 549614.68 | CS12: =K12-CR12 -> 839967.97 | CU12: =D12 -> ARS | CV12: =VLOOKUP(CU12,DF:DG,2,0) -> 0.0006918517 | CW12: =K12*CV12 -> 961.38512 | CX12: =BN12*CV12 -> 40.04169 | CY12: =BT12*CV12 -> 144.20777 | CZ12: =BZ12*CV12 -> 128.70543 | DA12: =CF12*CV12 -> 28.841554 | DB12: =CL12*CV12 -> 38.455405 | DC12: =CS12*CV12 -> 581.13327 | DD12: =VLOOKUP(A12,'Billing Report'!H:I,2,FALSE) -> OT466 Rentas - Alcance - Twitter | DF12: BGN | DG12: 0.60864087
A13: 40789966 | B13: T2751490 | C13: 275149001 | D13: ARS | G13: 443772.08 | J13: =VLOOKUP($B13,'IMS Commission List'!E:CE,79,0)/100 -> 0.15 | K13: =SUM(E13:I13) -> 443772.08 | L13: =VLOOKUP($B13,'IMS Commission List'!E:V,18,0) -> ARS | M13: 1 | N13: =VLOOKUP($B13,'IMS Commission List'!E:T,16,0) -> MX | O13: =VLOOKUP($B13,'IMS Commission List'!E:CF,80,0) -> 0.049 | P13: =VLOOKUP($B13,'IMS Commission List'!E:CG,81,0) -> 0.1575 | Q13: =VLOOKUP($B13,'IMS Commission List'!E:CP,90,0) -> 0.03 | R13: =VLOOKUP($B13,'IMS Commission List'!E:CQ,91,0) -> 0.04 | S13: =$E13*$M13 -> 0 | T13: =$F13*$M13 -> 0 | U13: =$G13*$M13 -> 443772.08 | V13: =$H13*$M13 -> 0 | W13: =$I13*$M13 -> 0 | X13: =$K13*$M13 -> 443772.08 | Y13: =(S13*$O13)*(1-J13) -> 0 | Z13: =(T13*$O13)*(1-J13) -> 0 | AA13: =(U13*$O13)*(1-J13) -> 18483.107 | AB13: =(V13*$O13)*(1-J13) -> 0 | AC13: =(W13*$O13)*(1-J13) -> 0 | AD13: =SUM(Y13:AC13) -> 18483.107 | AE13: =S13*$J13 -> 0 | AF13: =T13*$J13 -> 0 | AG13: =U13*$J13 -> 66565.812 | AH13: =V13*$J13 -> 0 | AI13: =W13*$J13 -> 0 | AJ13: =SUM(AE13:AI13) -> 66565.812 | AK13: =($P13*S13)*(1-$J13) -> 0 | AL13: =($P13*T13)*(1-$J13) -> 0 | AM13: =($P13*U13)*(1-$J13) -> 59409.987 | AN13: =($P13*V13)*(1-$J13) -> 0 | AO13: =($P13*W13)*(1-$J13) -> 0 | AP13: =SUM(AK13:AO13) -> 59409.987 | AQ13: =S13*$Q13 -> 0 | AR13: =T13*$Q13 -> 0 | AS13: =U13*$Q13 -> 13313.162 | AT13: =V13*$Q13 -> 0 | AU13: =W13*$Q13 -> 0 | AV13: =SUM(AQ13:AU13) -> 13313.162 | AW13: =S13*$R13 -> 0 | AX13: =T13*$R13 -> 0 | AY13: =U13*$R13 -> 17750.883 | AZ13: =V13*$R13 -> 0 | BA13: =W13*$R13 -> 0 | BB13: =SUM(AW13:BA13) -> 17750.883 | BC13: =$Y13+$AE13+$AK13+$AQ13+AW13 -> 0 | BD13: =$Z13+$AF13+$AL13+AR13+AX13 -> 0 | BE13: =$AA13+$AG13+$AM13+AS13+AY13 -> 175522.95 | BF13: =$AB13+$AH13+$AN13+AT13+AZ13 -> 0 | BG13: =$AC13+$AI13+$AO13+AU13+BA13 -> 0 | BH13: =SUM(BC13:BG13) -> 175522.95 | BI13: =$Y13/$M13 -> 0 | BJ13: =$Z13/$M13 -> 0 | BK13: =$AA13/$M13 -> 18483.107 | BL13: =$AB13/$M13 -> 0 | BM13: =$AC13/$M13 -> 0 | BN13: =$AD13/$M13 -> 18483.107 | BO13: =$AE13/$M13 -> 0 | BP13: =$AF13/$M13 -> 0 | BQ13: =$AG13/$M13 -> 66565.812 | BR13: =$AH13/$M13 -> 0 | BS13: =$AI13/$M13 -> 0 | BT13: =$AJ13/$M13 -> 66565.812 | BU13: =$AK13/$M13 -> 0 | BV13: =$AL13/$M13 -> 0 | BW13: =$AM13/$M13 -> 59409.987 | BX13: =$AN13/$M13 -> 0 | BY13: =$AO13/$M13 -> 0 | BZ13: =$AP13/$M13 -> 59409.987 | CA13: =AQ13/$M13 -> 0 | CB13: =AR13/$M13 -> 0 | CC13: =AS13/$M13 -> 13313.162 | CD13: =AT13/$M13 -> 0 | CE13: =AU13/$M13 -> 0 | CF13: =AV13/$M13 -> 13313.162 | CG13: =AW13/$M13 -> 0 | CH13: =AX13/$M13 -> 0 | ... CL13: =BB13/$M13 -> 17750.883 | CM13: =$BC13/$M13 -> 0 | CN13: =$BD13/$M13 -> 0 | CO13: =$BE13/$M13 -> 175522.95 | CP13: =$BF13/$M13 -> 0 | CQ13: =$BG13/$M13 -> 0 | CR13: =SUM(CM13:CQ13) -> 175522.95 | CS13: =K13-CR13 -> 268249.13 | CU13: =D13 -> ARS | CV13: =VLOOKUP(CU13,DF:DG,2,0) -> 0.0006918517 | CW13: =K13*CV13 -> 307.02447 | CX13: =BN13*CV13 -> 12.787569 | CY13: =BT13*CV13 -> 46.05367 | CZ13: =BZ13*CV13 -> 41.102901 | DA13: =CF13*CV13 -> 9.210734 | DB13: =CL13*CV13 -> 12.280979 | DC13: =CS13*CV13 -> 185.58862 | DD13: =VLOOKUP(A13,'Billing Report'!H:I,2,FALSE) -> OT429-V3 Cordobesa Verano - Alcance - Twitter - Capsulas de Video (MALEVO) | DF13: BHD | DG13: 2.6525903
A14: 40789854 | B14: T2751490 | C14: 275149001 | D14: ARS | G14: 61583.81 | J14: =VLOOKUP($B14,'IMS Commission List'!E:CE,79,0)/100 -> 0.15 | K14: =SUM(E14:I14) -> 61583.81 | L14: =VLOOKUP($B14,'IMS Commission List'!E:V,18,0) -> ARS | M14: 1 | N14: =VLOOKUP($B14,'IMS Commission List'!E:T,16,0) -> MX | O14: =VLOOKUP($B14,'IMS Commission List'!E:CF,80,0) -> 0.049 | P14: =VLOOKUP($B14,'IMS Commission List'!E:CG,81,0) -> 0.1575 | Q14: =VLOOKUP($B14,'IMS Commission List'!E:CP,90,0) -> 0.03 | R14: =VLOOKUP($B14,'IMS Commission List'!E:CQ,91,0) -> 0.04 | S14: =$E14*$M14 -> 0 | T14: =$F14*$M14 -> 0 | U14: =$G14*$M14 -> 61583.81 | V14: =$H14*$M14 -> 0 | W14: =$I14*$M14 -> 0 | X14: =$K14*$M14 -> 61583.81 | Y14: =(S14*$O14)*(1-J14) -> 0 | Z14: =(T14*$O14)*(1-J14) -> 0 | AA14: =(U14*$O14)*(1-J14) -> 2564.9657 | AB14: =(V14*$O14)*(1-J14) -> 0 | AC14: =(W14*$O14)*(1-J14) -> 0 | AD14: =SUM(Y14:AC14) -> 2564.9657 | AE14: =S14*$J14 -> 0 | AF14: =T14*$J14 -> 0 | AG14: =U14*$J14 -> 9237.5715 | AH14: =V14*$J14 -> 0 | AI14: =W14*$J14 -> 0 | AJ14: =SUM(AE14:AI14) -> 9237.5715 | AK14: =($P14*S14)*(1-$J14) -> 0 | AL14: =($P14*T14)*(1-$J14) -> 0 | AM14: =($P14*U14)*(1-$J14) -> 8244.5326 | AN14: =($P14*V14)*(1-$J14) -> 0 | AO14: =($P14*W14)*(1-$J14) -> 0 | AP14: =SUM(AK14:AO14) -> 8244.5326 | AQ14: =S14*$Q14 -> 0 | AR14: =T14*$Q14 -> 0 | AS14: =U14*$Q14 -> 1847.5143 | AT14: =V14*$Q14 -> 0 | AU14: =W14*$Q14 -> 0 | AV14: =SUM(AQ14:AU14) -> 1847.5143 | AW14: =S14*$R14 -> 0 | AX14: =T14*$R14 -> 0 | AY14: =U14*$R14 -> 2463.3524 | AZ14: =V14*$R14 -> 0 | BA14: =W14*$R14 -> 0 | BB14: =SUM(AW14:BA14) -> 2463.3524 | BC14: =$Y14+$AE14+$AK14+$AQ14+AW14 -> 0 | BD14: =$Z14+$AF14+$AL14+AR14+AX14 -> 0 | BE14: =$AA14+$AG14+$AM14+AS14+AY14 -> 24357.936 | BF14: =$AB14+$AH14+$AN14+AT14+AZ14 -> 0 | BG14: =$AC14+$AI14+$AO14+AU14+BA14 -> 0 | BH14: =SUM(BC14:BG14) -> 24357.936 | BI14: =$Y14/$M14 -> 0 | BJ14: =$Z14/$M14 -> 0 | BK14: =$AA14/$M14 -> 2564.9657 | BL14: =$AB14/$M14 -> 0 | BM14: =$AC14/$M14 -> 0 | BN14: =$AD14/$M14 -> 2564.9657 | BO14: =$AE14/$M14 -> 0 | BP14: =$AF14/$M14 -> 0 | BQ14: =$AG14/$M14 -> 9237.5715 | BR14: =$AH14/$M14 -> 0 | BS14: =$AI14/$M14 -> 0 | BT14: =$AJ14/$M14 -> 9237.5715 | BU14: =$AK14/$M14 -> 0 | BV14: =$AL14/$M14 -> 0 | BW14: =$AM14/$M14 -> 8244.5326 | BX14: =$AN14/$M14 -> 0 | BY14: =$AO14/$M14 -> 0 | BZ14: =$AP14/$M14 -> 8244.5326 | CA14: =AQ14/$M14 -> 0 | CB14: =AR14/$M14 -> 0 | CC14: =AS14/$M14 -> 1847.5143 | CD14: =AT14/$M14 -> 0 | CE14: =AU14/$M14 -> 0 | CF14: =AV14/$M14 -> 1847.5143 | CG14: =AW14/$M14 -> 0 | CH14: =AX14/$M14 -> 0 | ... CL14: =BB14/$M14 -> 2463.3524 | CM14: =$BC14/$M14 -> 0 | CN14: =$BD14/$M14 -> 0 | CO14: =$BE14/$M14 -> 24357.936 | CP14: =$BF14/$M14 -> 0 | CQ14: =$BG14/$M14 -> 0 | CR14: =SUM(CM14:CQ14) -> 24357.936 | CS14: =K14-CR14 -> 37225.874 | CU14: =D14 -> ARS | CV14: =VLOOKUP(CU14,DF:DG,2,0) -> 0.0006918517 | CW14: =K14*CV14 -> 42.606864 | CX14: =BN14*CV14 -> 1.7745759 | CY14: =BT14*CV14 -> 6.3910295 | CZ14: =BZ14*CV14 -> 5.7039939 | DA14: =CF14*CV14 -> 1.2782059 | DB14: =CL14*CV14 -> 1.7042745 | DC14: =CS14*CV14 -> 25.754784 | DD14: =VLOOKUP(A14,'Billing Report'!H:I,2,FALSE) -> OT429-V3 Cordobesa Verano - Alcance - Twitter - PROMO PEAJE | DF14: BRL | DG14: 0.19166396
A15: 40789845 | B15: T2751490 | C15: 275149001 | D15: ARS | G15: 319263.44 | J15: =VLOOKUP($B15,'IMS Commission List'!E:CE,79,0)/100 -> 0.15 | K15: =SUM(E15:I15) -> 319263.44 | L15: =VLOOKUP($B15,'IMS Commission List'!E:V,18,0) -> ARS | M15: 1 | N15: =VLOOKUP($B15,'IMS Commission List'!E:T,16,0) -> MX | O15: =VLOOKUP($B15,'IMS Commission List'!E:CF,80,0) -> 0.049 | P15: =VLOOKUP($B15,'IMS Commission List'!E:CG,81,0) -> 0.1575 | Q15: =VLOOKUP($B15,'IMS Commission List'!E:CP,90,0) -> 0.03 | R15: =VLOOKUP($B15,'IMS Commission List'!E:CQ,91,0) -> 0.04 | S15: =$E15*$M15 -> 0 | T15: =$F15*$M15 -> 0 | U15: =$G15*$M15 -> 319263.44 | V15: =$H15*$M15 -> 0 | W15: =$I15*$M15 -> 0 | X15: =$K15*$M15 -> 319263.44 | Y15: =(S15*$O15)*(1-J15) -> 0 | Z15: =(T15*$O15)*(1-J15) -> 0 | AA15: =(U15*$O15)*(1-J15) -> 13297.322 | AB15: =(V15*$O15)*(1-J15) -> 0 | AC15: =(W15*$O15)*(1-J15) -> 0 | AD15: =SUM(Y15:AC15) -> 13297.322 | AE15: =S15*$J15 -> 0 | AF15: =T15*$J15 -> 0 | AG15: =U15*$J15 -> 47889.516 | AH15: =V15*$J15 -> 0 | AI15: =W15*$J15 -> 0 | AJ15: =SUM(AE15:AI15) -> 47889.516 | AK15: =($P15*S15)*(1-$J15) -> 0 | AL15: =($P15*T15)*(1-$J15) -> 0 | AM15: =($P15*U15)*(1-$J15) -> 42741.393 | AN15: =($P15*V15)*(1-$J15) -> 0 | AO15: =($P15*W15)*(1-$J15) -> 0 | AP15: =SUM(AK15:AO15) -> 42741.393 | AQ15: =S15*$Q15 -> 0 | AR15: =T15*$Q15 -> 0 | AS15: =U15*$Q15 -> 9577.9032 | AT15: =V15*$Q15 -> 0 | AU15: =W15*$Q15 -> 0 | AV15: =SUM(AQ15:AU15) -> 9577.9032 | AW15: =S15*$R15 -> 0 | AX15: =T15*$R15 -> 0 | AY15: =U15*$R15 -> 12770.538 | AZ15: =V15*$R15 -> 0 | BA15: =W15*$R15 -> 0 | BB15: =SUM(AW15:BA15) -> 12770.538 | BC15: =$Y15+$AE15+$AK15+$AQ15+AW15 -> 0 | BD15: =$Z15+$AF15+$AL15+AR15+AX15 -> 0 | BE15: =$AA15+$AG15+$AM15+AS15+AY15 -> 126276.67 | BF15: =$AB15+$AH15+$AN15+AT15+AZ15 -> 0 | BG15: =$AC15+$AI15+$AO15+AU15+BA15 -> 0 | BH15: =SUM(BC15:BG15) -> 126276.67 | BI15: =$Y15/$M15 -> 0 | BJ15: =$Z15/$M15 -> 0 | BK15: =$AA15/$M15 -> 13297.322 | BL15: =$AB15/$M15 -> 0 | BM15: =$AC15/$M15 -> 0 | BN15: =$AD15/$M15 -> 13297.322 | BO15: =$AE15/$M15 -> 0 | BP15: =$AF15/$M15 -> 0 | BQ15: =$AG15/$M15 -> 47889.516 | BR15: =$AH15/$M15 -> 0 | BS15: =$AI15/$M15 -> 0 | BT15: =$AJ15/$M15 -> 47889.516 | BU15: =$AK15/$M15 -> 0 | BV15: =$AL15/$M15 -> 0 | BW15: =$AM15/$M15 -> 42741.393 | BX15: =$AN15/$M15 -> 0 | BY15: =$AO15/$M15 -> 0 | BZ15: =$AP15/$M15 -> 42741.393 | CA15: =AQ15/$M15 -> 0 | CB15: =AR15/$M15 -> 0 | CC15: =AS15/$M15 -> 9577.9032 | CD15: =AT15/$M15 -> 0 | CE15: =AU15/$M15 -> 0 | CF15: =AV15/$M15 -> 9577.9032 | CG15: =AW15/$M15 -> 0 | CH15: =AX15/$M15 -> 0 | ... CL15: =BB15/$M15 -> 12770.538 | CM15: =$BC15/$M15 -> 0 | CN15: =$BD15/$M15 -> 0 | CO15: =$BE15/$M15 -> 126276.67 | CP15: =$BF15/$M15 -> 0 | CQ15: =$BG15/$M15 -> 0 | CR15: =SUM(CM15:CQ15) -> 126276.67 | CS15: =K15-CR15 -> 192986.77 | CU15: =D15 -> ARS | CV15: =VLOOKUP(CU15,DF:DG,2,0) -> 0.0006918517 | CW15: =K15*CV15 -> 220.88295 | CX15: =BN15*CV15 -> 9.199775 | CY15: =BT15*CV15 -> 33.132443 | CZ15: =BZ15*CV15 -> 29.570705 | DA15: =CF15*CV15 -> 6.6264886 | DB15: =CL15*CV15 -> 8.8353181 | DC15: =CS15*CV15 -> 133.51822 | DD15: =VLOOKUP(A15,'Billing Report'!H:I,2,FALSE) -> OT429-V3 Cordobesa Verano - Alcance - Twitter - PROMO Festivales y Espectáculos | DF15: BYR | DG15: 3.51832e-05
A16: 40789826 | B16: T2751490 | C16: 275149001 | D16: ARS | G16: 61670.34 | J16: =VLOOKUP($B16,'IMS Commission List'!E:CE,79,0)/100 -> 0.15 | K16: =SUM(E16:I16) -> 61670.34 | L16: =VLOOKUP($B16,'IMS Commission List'!E:V,18,0) -> ARS | M16: 1 | N16: =VLOOKUP($B16,'IMS Commission List'!E:T,16,0) -> MX | O16: =VLOOKUP($B16,'IMS Commission List'!E:CF,80,0) -> 0.049 | P16: =VLOOKUP($B16,'IMS Commission List'!E:CG,81,0) -> 0.1575 | Q16: =VLOOKUP($B16,'IMS Commission List'!E:CP,90,0) -> 0.03 | R16: =VLOOKUP($B16,'IMS Commission List'!E:CQ,91,0) -> 0.04 | S16: =$E16*$M16 -> 0 | T16: =$F16*$M16 -> 0 | U16: =$G16*$M16 -> 61670.34 | V16: =$H16*$M16 -> 0 | W16: =$I16*$M16 -> 0 | X16: =$K16*$M16 -> 61670.34 | Y16: =(S16*$O16)*(1-J16) -> 0 | Z16: =(T16*$O16)*(1-J16) -> 0 | AA16: =(U16*$O16)*(1-J16) -> 2568.5697 | AB16: =(V16*$O16)*(1-J16) -> 0 | AC16: =(W16*$O16)*(1-J16) -> 0 | AD16: =SUM(Y16:AC16) -> 2568.5697 | AE16: =S16*$J16 -> 0 | AF16: =T16*$J16 -> 0 | AG16: =U16*$J16 -> 9250.551 | AH16: =V16*$J16 -> 0 | AI16: =W16*$J16 -> 0 | AJ16: =SUM(AE16:AI16) -> 9250.551 | AK16: =($P16*S16)*(1-$J16) -> 0 | AL16: =($P16*T16)*(1-$J16) -> 0 | AM16: =($P16*U16)*(1-$J16) -> 8256.1168 | AN16: =($P16*V16)*(1-$J16) -> 0 | AO16: =($P16*W16)*(1-$J16) -> 0 | AP16: =SUM(AK16:AO16) -> 8256.1168 | AQ16: =S16*$Q16 -> 0 | AR16: =T16*$Q16 -> 0 | AS16: =U16*$Q16 -> 1850.1102 | AT16: =V16*$Q16 -> 0 | AU16: =W16*$Q16 -> 0 | AV16: =SUM(AQ16:AU16) -> 1850.1102 | AW16: =S16*$R16 -> 0 | AX16: =T16*$R16 -> 0 | AY16: =U16*$R16 -> 2466.8136 | AZ16: =V16*$R16 -> 0 | BA16: =W16*$R16 -> 0 | BB16: =SUM(AW16:BA16) -> 2466.8136 | BC16: =$Y16+$AE16+$AK16+$AQ16+AW16 -> 0 | BD16: =$Z16+$AF16+$AL16+AR16+AX16 -> 0 | BE16: =$AA16+$AG16+$AM16+AS16+AY16 -> 24392.161 | BF16: =$AB16+$AH16+$AN16+AT16+AZ16 -> 0 | BG16: =$AC16+$AI16+$AO16+AU16+BA16 -> 0 | BH16: =SUM(BC16:BG16) -> 24392.161 | BI16: =$Y16/$M16 -> 0 | BJ16: =$Z16/$M16 -> 0 | BK16: =$AA16/$M16 -> 2568.5697 | BL16: =$AB16/$M16 -> 0 | BM16: =$AC16/$M16 -> 0 | BN16: =$AD16/$M16 -> 2568.5697 | BO16: =$AE16/$M16 -> 0 | BP16: =$AF16/$M16 -> 0 | BQ16: =$AG16/$M16 -> 9250.551 | BR16: =$AH16/$M16 -> 0 | BS16: =$AI16/$M16 -> 0 | BT16: =$AJ16/$M16 -> 9250.551 | BU16: =$AK16/$M16 -> 0 | BV16: =$AL16/$M16 -> 0 | BW16: =$AM16/$M16 -> 8256.1168 | BX16: =$AN16/$M16 -> 0 | BY16: =$AO16/$M16 -> 0 | BZ16: =$AP16/$M16 -> 8256.1168 | CA16: =AQ16/$M16 -> 0 | CB16: =AR16/$M16 -> 0 | CC16: =AS16/$M16 -> 1850.1102 | CD16: =AT16/$M16 -> 0 | CE16: =AU16/$M16 -> 0 | CF16: =AV16/$M16 -> 1850.1102 | CG16: =AW16/$M16 -> 0 | CH16: =AX16/$M16 -> 0 | ... CL16: =BB16/$M16 -> 2466.8136 | CM16: =$BC16/$M16 -> 0 | CN16: =$BD16/$M16 -> 0 | CO16: =$BE16/$M16 -> 24392.161 | CP16: =$BF16/$M16 -> 0 | CQ16: =$BG16/$M16 -> 0 | CR16: =SUM(CM16:CQ16) -> 24392.161 | CS16: =K16-CR16 -> 37278.179 | CU16: =D16 -> ARS | CV16: =VLOOKUP(CU16,DF:DG,2,0) -> 0.0006918517 | CW16: =K16*CV16 -> 42.66673 | CX16: =BN16*CV16 -> 1.7770693 | CY16: =BT16*CV16 -> 6.4000094 | CZ16: =BZ16*CV16 -> 5.7120084 | DA16: =CF16*CV16 -> 1.2800019 | DB16: =CL16*CV16 -> 1.7066692 | DC16: =CS16*CV16 -> 25.790971 | DD16: =VLOOKUP(A16,'Billing Report'!H:I,2,FALSE) -> OT429-V3 Cordobesa Verano - Alcance - Twitter - PROMO SUPERMERCADO | DF16: CAD | DG16: 0.73817354
A17: 37183205 | B17: T2767832 | C17: 276783201 | D17: ARS | G17: 3113913.1 | J17: =VLOOKUP($B17,'IMS Commission List'!E:CE,79,0)/100 -> 0.15 | K17: =SUM(E17:I17) -> 3113913.1 | L17: =VLOOKUP($B17,'IMS Commission List'!E:V,18,0) -> ARS | M17: 1 | N17: =VLOOKUP($B17,'IMS Commission List'!E:T,16,0) -> MX | O17: =VLOOKUP($B17,'IMS Commission List'!E:CF,80,0) -> 0.049 | P17: =VLOOKUP($B17,'IMS Commission List'!E:CG,81,0) -> 0.1575 | Q17: =VLOOKUP($B17,'IMS Commission List'!E:CP,90,0) -> 0.03 | R17: =VLOOKUP($B17,'IMS Commission List'!E:CQ,91,0) -> 0.04 | S17: =$E17*$M17 -> 0 | T17: =$F17*$M17 -> 0 | U17: =$G17*$M17 -> 3113913.1 | V17: =$H17*$M17 -> 0 | W17: =$I17*$M17 -> 0 | X17: =$K17*$M17 -> 3113913.1 | Y17: =(S17*$O17)*(1-J17) -> 0 | Z17: =(T17*$O17)*(1-J17) -> 0 | AA17: =(U17*$O17)*(1-J17) -> 129694.48 | AB17: =(V17*$O17)*(1-J17) -> 0 | AC17: =(W17*$O17)*(1-J17) -> 0 | AD17: =SUM(Y17:AC17) -> 129694.48 | AE17: =S17*$J17 -> 0 | AF17: =T17*$J17 -> 0 | AG17: =U17*$J17 -> 467086.96 | AH17: =V17*$J17 -> 0 | AI17: =W17*$J17 -> 0 | AJ17: =SUM(AE17:AI17) -> 467086.96 | AK17: =($P17*S17)*(1-$J17) -> 0 | AL17: =($P17*T17)*(1-$J17) -> 0 | AM17: =($P17*U17)*(1-$J17) -> 416875.11 | AN17: =($P17*V17)*(1-$J17) -> 0 | AO17: =($P17*W17)*(1-$J17) -> 0 | AP17: =SUM(AK17:AO17) -> 416875.11 | AQ17: =S17*$Q17 -> 0 | AR17: =T17*$Q17 -> 0 | AS17: =U17*$Q17 -> 93417.392 | AT17: =V17*$Q17 -> 0 | AU17: =W17*$Q17 -> 0 | AV17: =SUM(AQ17:AU17) -> 93417.392 | AW17: =S17*$R17 -> 0 | AX17: =T17*$R17 -> 0 | AY17: =U17*$R17 -> 124556.52 | AZ17: =V17*$R17 -> 0 | BA17: =W17*$R17 -> 0 | BB17: =SUM(AW17:BA17) -> 124556.52 | BC17: =$Y17+$AE17+$AK17+$AQ17+AW17 -> 0 | BD17: =$Z17+$AF17+$AL17+AR17+AX17 -> 0 | BE17: =$AA17+$AG17+$AM17+AS17+AY17 -> 1231630.5 | BF17: =$AB17+$AH17+$AN17+AT17+AZ17 -> 0 | BG17: =$AC17+$AI17+$AO17+AU17+BA17 -> 0 | BH17: =SUM(BC17:BG17) -> 1231630.5 | BI17: =$Y17/$M17 -> 0 | BJ17: =$Z17/$M17 -> 0 | BK17: =$AA17/$M17 -> 129694.48 | BL17: =$AB17/$M17 -> 0 | BM17: =$AC17/$M17 -> 0 | BN17: =$AD17/$M17 -> 129694.48 | BO17: =$AE17/$M17 -> 0 | BP17: =$AF17/$M17 -> 0 | BQ17: =$AG17/$M17 -> 467086.96 | BR17: =$AH17/$M17 -> 0 | BS17: =$AI17/$M17 -> 0 | BT17: =$AJ17/$M17 -> 467086.96 | BU17: =$AK17/$M17 -> 0 | BV17: =$AL17/$M17 -> 0 | BW17: =$AM17/$M17 -> 416875.11 | BX17: =$AN17/$M17 -> 0 | BY17: =$AO17/$M17 -> 0 | BZ17: =$AP17/$M17 -> 416875.11 | CA17: =AQ17/$M17 -> 0 | CB17: =AR17/$M17 -> 0 | CC17: =AS17/$M17 -> 93417.392 | CD17: =AT17/$M17 -> 0 | CE17: =AU17/$M17 -> 0 | CF17: =AV17/$M17 -> 93417.392 | CG17: =AW17/$M17 -> 0 | CH17: =AX17/$M17 -> 0 | ... CL17: =BB17/$M17 -> 124556.52 | CM17: =$BC17/$M17 -> 0 | CN17: =$BD17/$M17 -> 0 | CO17: =$BE17/$M17 -> 1231630.5 | CP17: =$BF17/$M17 -> 0 | CQ17: =$BG17/$M17 -> 0 | CR17: =SUM(CM17:CQ17) -> 1231630.5 | CS17: =K17-CR17 -> 1882282.6 | CU17: =D17 -> ARS | CV17: =VLOOKUP(CU17,DF:DG,2,0) -> 0.0006918517 | CW17: =K17*CV17 -> 2154.3661 | CX17: =BN17*CV17 -> 89.729346 | CY17: =BT17*CV17 -> 323.15491 | CZ17: =BZ17*CV17 -> 288.41576 | DA17: =CF17*CV17 -> 64.630982 | DB17: =CL17*CV17 -> 86.174642 | DC17: =CS17*CV17 -> 1302.2604 | DD17: =VLOOKUP(A17,'Billing Report'!H:I,2,FALSE) -> Banco Galicia 6 y 12 cuotas | DF17: CHF | DG17: 1.2994523
A18: 40860429 | B18: T2834460 | C18: 283446001 | D18: ARS | G18: 1208044.6 | J18: =VLOOKUP($B18,'IMS Commission List'!E:CE,79,0)/100 -> 0.15 | K18: =SUM(E18:I18) -> 1208044.6 | L18: =VLOOKUP($B18,'IMS Commission List'!E:V,18,0) -> ARS | M18: 1 | N18: =VLOOKUP($B18,'IMS Commission List'!E:T,16,0) -> MX | O18: =VLOOKUP($B18,'IMS Commission List'!E:CF,80,0) -> 0.049 | P18: =VLOOKUP($B18,'IMS Commission List'!E:CG,81,0) -> 0.1575 | Q18: =VLOOKUP($B18,'IMS Commission List'!E:CP,90,0) -> 0.03 | R18: =VLOOKUP($B18,'IMS Commission List'!E:CQ,91,0) -> 0.04 | S18: =$E18*$M18 -> 0 | T18: =$F18*$M18 -> 0 | U18: =$G18*$M18 -> 1208044.6 | V18: =$H18*$M18 -> 0 | W18: =$I18*$M18 -> 0 | X18: =$K18*$M18 -> 1208044.6 | Y18: =(S18*$O18)*(1-J18) -> 0 | Z18: =(T18*$O18)*(1-J18) -> 0 | AA18: =(U18*$O18)*(1-J18) -> 50315.059 | AB18: =(V18*$O18)*(1-J18) -> 0 | AC18: =(W18*$O18)*(1-J18) -> 0 | AD18: =SUM(Y18:AC18) -> 50315.059 | AE18: =S18*$J18 -> 0 | AF18: =T18*$J18 -> 0 | AG18: =U18*$J18 -> 181206.69 | AH18: =V18*$J18 -> 0 | AI18: =W18*$J18 -> 0 | AJ18: =SUM(AE18:AI18) -> 181206.69 | AK18: =($P18*S18)*(1-$J18) -> 0 | AL18: =($P18*T18)*(1-$J18) -> 0 | AM18: =($P18*U18)*(1-$J18) -> 161726.97 | AN18: =($P18*V18)*(1-$J18) -> 0 | AO18: =($P18*W18)*(1-$J18) -> 0 | AP18: =SUM(AK18:AO18) -> 161726.97 | AQ18: =S18*$Q18 -> 0 | AR18: =T18*$Q18 -> 0 | AS18: =U18*$Q18 -> 36241.339 | AT18: =V18*$Q18 -> 0 | AU18: =W18*$Q18 -> 0 | AV18: =SUM(AQ18:AU18) -> 36241.339 | AW18: =S18*$R18 -> 0 | AX18: =T18*$R18 -> 0 | AY18: =U18*$R18 -> 48321.785 | AZ18: =V18*$R18 -> 0 | BA18: =W18*$R18 -> 0 | BB18: =SUM(AW18:BA18) -> 48321.785 | BC18: =$Y18+$AE18+$AK18+$AQ18+AW18 -> 0 | BD18: =$Z18+$AF18+$AL18+AR18+AX18 -> 0 | BE18: =$AA18+$AG18+$AM18+AS18+AY18 -> 477811.85 | BF18: =$AB18+$AH18+$AN18+AT18+AZ18 -> 0 | BG18: =$AC18+$AI18+$AO18+AU18+BA18 -> 0 | BH18: =SUM(BC18:BG18) -> 477811.85 | BI18: =$Y18/$M18 -> 0 | BJ18: =$Z18/$M18 -> 0 | BK18: =$AA18/$M18 -> 50315.059 | BL18: =$AB18/$M18 -> 0 | BM18: =$AC18/$M18 -> 0 | BN18: =$AD18/$M18 -> 50315.059 | BO18: =$AE18/$M18 -> 0 | BP18: =$AF18/$M18 -> 0 | BQ18: =$AG18/$M18 -> 181206.69 | BR18: =$AH18/$M18 -> 0 | BS18: =$AI18/$M18 -> 0 | BT18: =$AJ18/$M18 -> 181206.69 | BU18: =$AK18/$M18 -> 0 | BV18: =$AL18/$M18 -> 0 | BW18: =$AM18/$M18 -> 161726.97 | BX18: =$AN18/$M18 -> 0 | BY18: =$AO18/$M18 -> 0 | BZ18: =$AP18/$M18 -> 161726.97 | CA18: =AQ18/$M18 -> 0 | CB18: =AR18/$M18 -> 0 | CC18: =AS18/$M18 -> 36241.339 | CD18: =AT18/$M18 -> 0 | CE18: =AU18/$M18 -> 0 | CF18: =AV18/$M18 -> 36241.339 | CG18: =AW18/$M18 -> 0 | CH18: =AX18/$M18 -> 0 | ... CL18: =BB18/$M18 -> 48321.785 | CM18: =$BC18/$M18 -> 0 | CN18: =$BD18/$M18 -> 0 | CO18: =$BE18/$M18 -> 477811.85 | CP18: =$BF18/$M18 -> 0 | CQ18: =$BG18/$M18 -> 0 | CR18: =SUM(CM18:CQ18) -> 477811.85 | CS18: =K18-CR18 -> 730232.78 | CU18: =D18 -> ARS | CV18: =VLOOKUP(CU18,DF:DG,2,0) -> 0.0006918517 | CW18: =K18*CV18 -> 835.78773 | CX18: =BN18*CV18 -> 34.810559 | CY18: =BT18*CV18 -> 125.36816 | CZ18: =BZ18*CV18 -> 111.89108 | DA18: =CF18*CV18 -> 25.073632 | DB18: =CL18*CV18 -> 33.431509 | DC18: =CS18*CV18 -> 505.21279 | DD18: =VLOOKUP(A18,'Billing Report'!H:I,2,FALSE) -> BULL_FLYBONDI_AR_TWITTER_TRAF_ALWAYSON_PRUEBA | DF18: CLP | DG18: 0.0011587177
... A35: 40045288 | B35: T3025948 | C35: 302594801 | D35: ARS | G35: 523174.23 | J35: =VLOOKUP($B35,'IMS Commission List'!E:CE,79,0)/100 -> 0.08 | K35: =SUM(E35:I35) -> 523174.23 | L35: =VLOOKUP($B35,'IMS Commission List'!E:V,18,0) -> ARS | M35: 1 | N35: =VLOOKUP($B35,'IMS Commission List'!E:T,16,0) -> MX | O35: =VLOOKUP($B35,'IMS Commission List'!E:CF,80,0) -> 0.049 | P35: =VLOOKUP($B35,'IMS Commission List'!E:CG,81,0) -> 0.1575 | Q35: =VLOOKUP($B35,'IMS Commission List'!E:CP,90,0) -> 0.03 | R35: =VLOOKUP($B35,'IMS Commission List'!E:CQ,91,0) -> 0.04 | S35: =$E35*$M35 -> 0 | T35: =$F35*$M35 -> 0 | U35: =$G35*$M35 -> 523174.23 | V35: =$H35*$M35 -> 0 | W35: =$I35*$M35 -> 0 | X35: =$K35*$M35 -> 523174.23 | Y35: =(S35*$O35)*(1-J35) -> 0 | Z35: =(T35*$O35)*(1-J35) -> 0 | AA35: =(U35*$O35)*(1-J35) -> 23584.694 | AB35: =(V35*$O35)*(1-J35) -> 0 | AC35: =(W35*$O35)*(1-J35) -> 0 | AD35: =SUM(Y35:AC35) -> 23584.694 | AE35: =S35*$J35 -> 0 | AF35: =T35*$J35 -> 0 | AG35: =U35*$J35 -> 41853.938 | AH35: =V35*$J35 -> 0 | AI35: =W35*$J35 -> 0 | AJ35: =SUM(AE35:AI35) -> 41853.938 | AK35: =($P35*S35)*(1-$J35) -> 0 | AL35: =($P35*T35)*(1-$J35) -> 0 | AM35: =($P35*U35)*(1-$J35) -> 75807.946 | AN35: =($P35*V35)*(1-$J35) -> 0 | AO35: =($P35*W35)*(1-$J35) -> 0 | AP35: =SUM(AK35:AO35) -> 75807.946 | AQ35: =S35*$Q35 -> 0 | AR35: =T35*$Q35 -> 0 | AS35: =U35*$Q35 -> 15695.227 | AT35: =V35*$Q35 -> 0 | AU35: =W35*$Q35 -> 0 | AV35: =SUM(AQ35:AU35) -> 15695.227 | AW35: =S35*$R35 -> 0 | AX35: =T35*$R35 -> 0 | AY35: =U35*$R35 -> 20926.969 | AZ35: =V35*$R35 -> 0 | BA35: =W35*$R35 -> 0 | BB35: =SUM(AW35:BA35) -> 20926.969 | BC35: =$Y35+$AE35+$AK35+$AQ35+AW35 -> 0 | BD35: =$Z35+$AF35+$AL35+AR35+AX35 -> 0 | BE35: =$AA35+$AG35+$AM35+AS35+AY35 -> 177868.77 | BF35: =$AB35+$AH35+$AN35+AT35+AZ35 -> 0 | BG35: =$AC35+$AI35+$AO35+AU35+BA35 -> 0 | BH35: =SUM(BC35:BG35) -> 177868.77 | BI35: =$Y35/$M35 -> 0 | BJ35: =$Z35/$M35 -> 0 | BK35: =$AA35/$M35 -> 23584.694 | BL35: =$AB35/$M35 -> 0 | BM35: =$AC35/$M35 -> 0 | BN35: =$AD35/$M35 -> 23584.694 | BO35: =$AE35/$M35 -> 0 | BP35: =$AF35/$M35 -> 0 | BQ35: =$AG35/$M35 -> 41853.938 | BR35: =$AH35/$M35 -> 0 | BS35: =$AI35/$M35 -> 0 | BT35: =$AJ35/$M35 -> 41853.938 | BU35: =$AK35/$M35 -> 0 | BV35: =$AL35/$M35 -> 0 | BW35: =$AM35/$M35 -> 75807.946 | BX35: =$AN35/$M35 -> 0 | BY35: =$AO35/$M35 -> 0 | BZ35: =$AP35/$M35 -> 75807.946 | CA35: =AQ35/$M35 -> 0 | CB35: =AR35/$M35 -> 0 | CC35: =AS35/$M35 -> 15695.227 | CD35: =AT35/$M35 -> 0 | CE35: =AU35/$M35 -> 0 | CF35: =AV35/$M35 -> 15695.227 | CG35: =AW35/$M35 -> 0 | CH35: =AX35/$M35 -> 0 | ... CL35: =BB35/$M35 -> 20926.969 | CM35: =$BC35/$M35 -> 0 | CN35: =$BD35/$M35 -> 0 | CO35: =$BE35/$M35 -> 177868.77 | CP35: =$BF35/$M35 -> 0 | CQ35: =$BG35/$M35 -> 0 | CR35: =SUM(CM35:CQ35) -> 177868.77 | CS35: =K35-CR35 -> 345305.46 | CU35: =D35 -> ARS | CV35: =VLOOKUP(CU35,DF:DG,2,0) -> 0.0006918517 | CW35: =K35*CV35 -> 361.95898 | CX35: =BN35*CV35 -> 16.317111 | CY35: =BT35*CV35 -> 28.956718 | CZ35: =BZ35*CV35 -> 52.447856 | DA35: =CF35*CV35 -> 10.858769 | DB35: =CL35*CV35 -> 14.478359 | DC35: =CS35*CV35 -> 238.90017 | DD35: =VLOOKUP(A35,'Billing Report'!H:I,2,FALSE) -> CX_AR_PR_PS_TW_TWI_AND_ALL_RAP_ALL_NA_00000_TAC_INS_INS | DF35: IQD | DG35: 0.0007629998
A36: (blank) | B36: T3094969 | C36: 309496901 | D36: ARS | G36: -31.88 | J36: =VLOOKUP($B36,'IMS Commission List'!E:CE,79,0)/100 -> 0.15 | K36: =SUM(E36:I36) -> -31.88 | L36: =VLOOKUP($B36,'IMS Commission List'!E:V,18,0) -> ARS | M36: 1 | N36: =VLOOKUP($B36,'IMS Commission List'!E:T,16,0) -> MX | O36: =VLOOKUP($B36,'IMS Commission List'!E:CF,80,0) -> 0.049 | P36: =VLOOKUP($B36,'IMS Commission List'!E:CG,81,0) -> 0.1575 | Q36: =VLOOKUP($B36,'IMS Commission List'!E:CP,90,0) -> 0.03 | R36: =VLOOKUP($B36,'IMS Commission List'!E:CQ,91,0) -> 0.04 | S36: =$E36*$M36 -> 0 | T36: =$F36*$M36 -> 0 | U36: =$G36*$M36 -> -31.88 | V36: =$H36*$M36 -> 0 | W36: =$I36*$M36 -> 0 | X36: =$K36*$M36 -> -31.88 | Y36: =(S36*$O36)*(1-J36) -> 0 | Z36: =(T36*$O36)*(1-J36) -> 0 | AA36: =(U36*$O36)*(1-J36) -> -1.327802 | AB36: =(V36*$O36)*(1-J36) -> 0 | AC36: =(W36*$O36)*(1-J36) -> 0 | AD36: =SUM(Y36:AC36) -> -1.327802 | AE36: =S36*$J36 -> 0 | AF36: =T36*$J36 -> 0 | AG36: =U36*$J36 -> -4.782 | AH36: =V36*$J36 -> 0 | AI36: =W36*$J36 -> 0 | AJ36: =SUM(AE36:AI36) -> -4.782 | AK36: =($P36*S36)*(1-$J36) -> 0 | AL36: =($P36*T36)*(1-$J36) -> 0 | AM36: =($P36*U36)*(1-$J36) -> -4.267935 | AN36: =($P36*V36)*(1-$J36) -> 0 | AO36: =($P36*W36)*(1-$J36) -> 0 | AP36: =SUM(AK36:AO36) -> -4.267935 | AQ36: =S36*$Q36 -> 0 | AR36: =T36*$Q36 -> 0 | AS36: =U36*$Q36 -> -0.9564 | AT36: =V36*$Q36 -> 0 | AU36: =W36*$Q36 -> 0 | AV36: =SUM(AQ36:AU36) -> -0.9564 | AW36: =S36*$R36 -> 0 | AX36: =T36*$R36 -> 0 | AY36: =U36*$R36 -> -1.2752 | AZ36: =V36*$R36 -> 0 | BA36: =W36*$R36 -> 0 | BB36: =SUM(AW36:BA36) -> -1.2752 | BC36: =$Y36+$AE36+$AK36+$AQ36+AW36 -> 0 | BD36: =$Z36+$AF36+$AL36+AR36+AX36 -> 0 | BE36: =$AA36+$AG36+$AM36+AS36+AY36 -> -12.609337 | BF36: =$AB36+$AH36+$AN36+AT36+AZ36 -> 0 | BG36: =$AC36+$AI36+$AO36+AU36+BA36 -> 0 | BH36: =SUM(BC36:BG36) -> -12.609337 | BI36: =$Y36/$M36 -> 0 | BJ36: =$Z36/$M36 -> 0 | BK36: =$AA36/$M36 -> -1.327802 | BL36: =$AB36/$M36 -> 0 | BM36: =$AC36/$M36 -> 0 | BN36: =$AD36/$M36 -> -1.327802 | BO36: =$AE36/$M36 -> 0 | BP36: =$AF36/$M36 -> 0 | BQ36: =$AG36/$M36 -> -4.782 | BR36: =$AH36/$M36 -> 0 | BS36: =$AI36/$M36 -> 0 | BT36: =$AJ36/$M36 -> -4.782 | BU36: =$AK36/$M36 -> 0 | BV36: =$AL36/$M36 -> 0 | BW36: =$AM36/$M36 -> -4.267935 | BX36: =$AN36/$M36 -> 0 | BY36: =$AO36/$M36 -> 0 | BZ36: =$AP36/$M36 -> -4.267935 | CA36: =AQ36/$M36 -> 0 | CB36: =AR36/$M36 -> 0 | CC36: =AS36/$M36 -> -0.9564 | CD36: =AT36/$M36 -> 0 | CE36: =AU36/$M36 -> 0 | CF36: =AV36/$M36 -> -0.9564 | CG36: =AW36/$M36 -> 0 | CH36: =AX36/$M36 -> 0 | ... CL36: =BB36/$M36 -> -1.2752 | CM36: =$BC36/$M36 -> 0 | CN36: =$BD36/$M36 -> 0 | CO36: =$BE36/$M36 -> -12.609337 | CP36: =$BF36/$M36 -> 0 | CQ36: =$BG36/$M36 -> 0 | CR36: =SUM(CM36:CQ36) -> -12.609337 | CS36: =K36-CR36 -> -19.270663 | CU36: =D36 -> ARS | CV36: =VLOOKUP(CU36,DF:DG,2,0) -> 0.0006918517 | CW36: =K36*CV36 -> -0.022056232 | CX36: =BN36*CV36 -> -0.00091864207 | CY36: =BT36*CV36 -> -0.0033084348 | CZ36: =BZ36*CV36 -> -0.0029527781 | DA36: =CF36*CV36 -> -0.00066168697 | DB36: =CL36*CV36 -> -0.00088224929 | DC36: =CS36*CV36 -> -0.013332441 | DD36: =VLOOKUP(A36,'Billing Report'!H:I,2,FALSE) -> #N/A | DF36: ISK | DG36: 0.0082094881
A37: 40930072 | B37: T3094969 | C37: 309496901 | D37: ARS | G37: 298461.32 | J37: =VLOOKUP($B37,'IMS Commission List'!E:CE,79,0)/100 -> 0.15 | K37: =SUM(E37:I37) -> 298461.32 | L37: =VLOOKUP($B37,'IMS Commission List'!E:V,18,0) -> ARS | M37: 1 | N37: =VLOOKUP($B37,'IMS Commission List'!E:T,16,0) -> MX | O37: =VLOOKUP($B37,'IMS Commission List'!E:CF,80,0) -> 0.049 | P37: =VLOOKUP($B37,'IMS Commission List'!E:CG,81,0) -> 0.1575 | Q37: =VLOOKUP($B37,'IMS Commission List'!E:CP,90,0) -> 0.03 | R37: =VLOOKUP($B37,'IMS Commission List'!E:CQ,91,0) -> 0.04 | S37: =$E37*$M37 -> 0 | T37: =$F37*$M37 -> 0 | U37: =$G37*$M37 -> 298461.32 | V37: =$H37*$M37 -> 0 | W37: =$I37*$M37 -> 0 | X37: =$K37*$M37 -> 298461.32 | Y37: =(S37*$O37)*(1-J37) -> 0 | Z37: =(T37*$O37)*(1-J37) -> 0 | AA37: =(U37*$O37)*(1-J37) -> 12430.914 | AB37: =(V37*$O37)*(1-J37) -> 0 | AC37: =(W37*$O37)*(1-J37) -> 0 | AD37: =SUM(Y37:AC37) -> 12430.914 | AE37: =S37*$J37 -> 0 | AF37: =T37*$J37 -> 0 | AG37: =U37*$J37 -> 44769.198 | AH37: =V37*$J37 -> 0 | AI37: =W37*$J37 -> 0 | AJ37: =SUM(AE37:AI37) -> 44769.198 | AK37: =($P37*S37)*(1-$J37) -> 0 | AL37: =($P37*T37)*(1-$J37) -> 0 | AM37: =($P37*U37)*(1-$J37) -> 39956.509 | AN37: =($P37*V37)*(1-$J37) -> 0 | AO37: =($P37*W37)*(1-$J37) -> 0 | AP37: =SUM(AK37:AO37) -> 39956.509 | AQ37: =S37*$Q37 -> 0 | AR37: =T37*$Q37 -> 0 | AS37: =U37*$Q37 -> 8953.8396 | AT37: =V37*$Q37 -> 0 | AU37: =W37*$Q37 -> 0 | AV37: =SUM(AQ37:AU37) -> 8953.8396 | AW37: =S37*$R37 -> 0 | AX37: =T37*$R37 -> 0 | AY37: =U37*$R37 -> 11938.453 | AZ37: =V37*$R37 -> 0 | BA37: =W37*$R37 -> 0 | BB37: =SUM(AW37:BA37) -> 11938.453 | BC37: =$Y37+$AE37+$AK37+$AQ37+AW37 -> 0 | BD37: =$Z37+$AF37+$AL37+AR37+AX37 -> 0 | BE37: =$AA37+$AG37+$AM37+AS37+AY37 -> 118048.91 | BF37: =$AB37+$AH37+$AN37+AT37+AZ37 -> 0 | BG37: =$AC37+$AI37+$AO37+AU37+BA37 -> 0 | BH37: =SUM(BC37:BG37) -> 118048.91 | BI37: =$Y37/$M37 -> 0 | BJ37: =$Z37/$M37 -> 0 | BK37: =$AA37/$M37 -> 12430.914 | BL37: =$AB37/$M37 -> 0 | BM37: =$AC37/$M37 -> 0 | BN37: =$AD37/$M37 -> 12430.914 | BO37: =$AE37/$M37 -> 0 | BP37: =$AF37/$M37 -> 0 | BQ37: =$AG37/$M37 -> 44769.198 | BR37: =$AH37/$M37 -> 0 | BS37: =$AI37/$M37 -> 0 | BT37: =$AJ37/$M37 -> 44769.198 | BU37: =$AK37/$M37 -> 0 | BV37: =$AL37/$M37 -> 0 | BW37: =$AM37/$M37 -> 39956.509 | BX37: =$AN37/$M37 -> 0 | BY37: =$AO37/$M37 -> 0 | BZ37: =$AP37/$M37 -> 39956.509 | CA37: =AQ37/$M37 -> 0 | CB37: =AR37/$M37 -> 0 | CC37: =AS37/$M37 -> 8953.8396 | CD37: =AT37/$M37 -> 0 | CE37: =AU37/$M37 -> 0 | CF37: =AV37/$M37 -> 8953.8396 | CG37: =AW37/$M37 -> 0 | CH37: =AX37/$M37 -> 0 | ... CL37: =BB37/$M37 -> 11938.453 | CM37: =$BC37/$M37 -> 0 | CN37: =$BD37/$M37 -> 0 | CO37: =$BE37/$M37 -> 118048.91 | CP37: =$BF37/$M37 -> 0 | CQ37: =$BG37/$M37 -> 0 | CR37: =SUM(CM37:CQ37) -> 118048.91 | CS37: =K37-CR37 -> 180412.41 | CU37: =D37 -> ARS | CV37: =VLOOKUP(CU37,DF:DG,2,0) -> 0.0006918517 | CW37: =K37*CV37 -> 206.49097 | CX37: =BN37*CV37 -> 8.600349 | CY37: =BT37*CV37 -> 30.973646 | CZ37: =BZ37*CV37 -> 27.643979 | DA37: =CF37*CV37 -> 6.1947291 | DB37: =CL37*CV37 -> 8.2596389 | DC37: =CS37*CV37 -> 124.81863 | DD37: =VLOOKUP(A37,'Billing Report'!H:I,2,FALSE) -> yoy-sv-brandformance-alcance | DF37: JPY | DG37: 0.0064860528
A38: 40775999 | B38: T3094969 | C38: 309496901 | D38: ARS | G38: 311760.77 | J38: =VLOOKUP($B38,'IMS Commission List'!E:CE,79,0)/100 -> 0.15 | K38: =SUM(E38:I38) -> 311760.77 | L38: =VLOOKUP($B38,'IMS Commission List'!E:V,18,0) -> ARS | M38: 1 | N38: =VLOOKUP($B38,'IMS Commission List'!E:T,16,0) -> MX | O38: =VLOOKUP($B38,'IMS Commission List'!E:CF,80,0) -> 0.049 | P38: =VLOOKUP($B38,'IMS Commission List'!E:CG,81,0) -> 0.1575 | Q38: =VLOOKUP($B38,'IMS Commission List'!E:CP,90,0) -> 0.03 | R38: =VLOOKUP($B38,'IMS Commission List'!E:CQ,91,0) -> 0.04 | S38: =$E38*$M38 -> 0 | T38: =$F38*$M38 -> 0 | U38: =$G38*$M38 -> 311760.77 | V38: =$H38*$M38 -> 0 | W38: =$I38*$M38 -> 0 | X38: =$K38*$M38 -> 311760.77 | Y38: =(S38*$O38)*(1-J38) -> 0 | Z38: =(T38*$O38)*(1-J38) -> 0 | AA38: =(U38*$O38)*(1-J38) -> 12984.836 | AB38: =(V38*$O38)*(1-J38) -> 0 | AC38: =(W38*$O38)*(1-J38) -> 0 | AD38: =SUM(Y38:AC38) -> 12984.836 | AE38: =S38*$J38 -> 0 | AF38: =T38*$J38 -> 0 | AG38: =U38*$J38 -> 46764.115 | AH38: =V38*$J38 -> 0 | AI38: =W38*$J38 -> 0 | AJ38: =SUM(AE38:AI38) -> 46764.115 | AK38: =($P38*S38)*(1-$J38) -> 0 | AL38: =($P38*T38)*(1-$J38) -> 0 | AM38: =($P38*U38)*(1-$J38) -> 41736.973 | AN38: =($P38*V38)*(1-$J38) -> 0 | AO38: =($P38*W38)*(1-$J38) -> 0 | AP38: =SUM(AK38:AO38) -> 41736.973 | AQ38: =S38*$Q38 -> 0 | AR38: =T38*$Q38 -> 0 | AS38: =U38*$Q38 -> 9352.8231 | AT38: =V38*$Q38 -> 0 | AU38: =W38*$Q38 -> 0 | AV38: =SUM(AQ38:AU38) -> 9352.8231 | AW38: =S38*$R38 -> 0 | AX38: =T38*$R38 -> 0 | AY38: =U38*$R38 -> 12470.431 | AZ38: =V38*$R38 -> 0 | BA38: =W38*$R38 -> 0 | BB38: =SUM(AW38:BA38) -> 12470.431 | BC38: =$Y38+$AE38+$AK38+$AQ38+AW38 -> 0 | BD38: =$Z38+$AF38+$AL38+AR38+AX38 -> 0 | BE38: =$AA38+$AG38+$AM38+AS38+AY38 -> 123309.18 | BF38: =$AB38+$AH38+$AN38+AT38+AZ38 -> 0 | BG38: =$AC38+$AI38+$AO38+AU38+BA38 -> 0 | BH38: =SUM(BC38:BG38) -> 123309.18 | BI38: =$Y38/$M38 -> 0 | BJ38: =$Z38/$M38 -> 0 | BK38: =$AA38/$M38 -> 12984.836 | BL38: =$AB38/$M38 -> 0 | BM38: =$AC38/$M38 -> 0 | BN38: =$AD38/$M38 -> 12984.836 | BO38: =$AE38/$M38 -> 0 | BP38: =$AF38/$M38 -> 0 | BQ38: =$AG38/$M38 -> 46764.115 | BR38: =$AH38/$M38 -> 0 | BS38: =$AI38/$M38 -> 0 | BT38: =$AJ38/$M38 -> 46764.115 | BU38: =$AK38/$M38 -> 0 | BV38: =$AL38/$M38 -> 0 | BW38: =$AM38/$M38 -> 41736.973 | BX38: =$AN38/$M38 -> 0 | BY38: =$AO38/$M38 -> 0 | BZ38: =$AP38/$M38 -> 41736.973 | CA38: =AQ38/$M38 -> 0 | CB38: =AR38/$M38 -> 0 | CC38: =AS38/$M38 -> 9352.8231 | CD38: =AT38/$M38 -> 0 | CE38: =AU38/$M38 -> 0 | CF38: =AV38/$M38 -> 9352.8231 | CG38: =AW38/$M38 -> 0 | CH38: =AX38/$M38 -> 0 | ... CL38: =BB38/$M38 -> 12470.431 | CM38: =$BC38/$M38 -> 0 | CN38: =$BD38/$M38 -> 0 | CO38: =$BE38/$M38 -> 123309.18 | CP38: =$BF38/$M38 -> 0 | CQ38: =$BG38/$M38 -> 0 | CR38: =SUM(CM38:CQ38) -> 123309.18 | CS38: =K38-CR38 -> 188451.59 | CU38: =D38 -> ARS | CV38: =VLOOKUP(CU38,DF:DG,2,0) -> 0.0006918517 | CW38: =K38*CV38 -> 215.69222 | CX38: =BN38*CV38 -> 8.9835809 | CY38: =BT38*CV38 -> 32.353833 | CZ38: =BZ38*CV38 -> 28.875796 | DA38: =CF38*CV38 -> 6.4707666 | DB38: =CL38*CV38 -> 8.6276887 | DC38: =CS38*CV38 -> 130.38055 | DD38: =VLOOKUP(A38,'Billing Report'!H:I,2,FALSE) -> yoy-brandformance-alcance | DF38: KES | DG38: 0.0077470997
A39: 39718034 | B39: T3101174 | C39: 310117401 | D39: ARS | G39: 2007664.5 | J39: =VLOOKUP($B39,'IMS Commission List'!E:CE,79,0)/100 -> 0.15 | K39: =SUM(E39:I39) -> 2007664.5 | L39: =VLOOKUP($B39,'IMS Commission List'!E:V,18,0) -> ARS | M39: 1 | N39: =VLOOKUP($B39,'IMS Commission List'!E:T,16,0) -> MX | O39: =VLOOKUP($B39,'IMS Commission List'!E:CF,80,0) -> 0.049 | P39: =VLOOKUP($B39,'IMS Commission List'!E:CG,81,0) -> 0.1575 | Q39: =VLOOKUP($B39,'IMS Commission List'!E:CP,90,0) -> 0.03 | R39: =VLOOKUP($B39,'IMS Commission List'!E:CQ,91,0) -> 0.04 | S39: =$E39*$M39 -> 0 | T39: =$F39*$M39 -> 0 | U39: =$G39*$M39 -> 2007664.5 | V39: =$H39*$M39 -> 0 | W39: =$I39*$M39 -> 0 | X39: =$K39*$M39 -> 2007664.5 | Y39: =(S39*$O39)*(1-J39) -> 0 | Z39: =(T39*$O39)*(1-J39) -> 0 | AA39: =(U39*$O39)*(1-J39) -> 83619.226 | AB39: =(V39*$O39)*(1-J39) -> 0 | AC39: =(W39*$O39)*(1-J39) -> 0 | AD39: =SUM(Y39:AC39) -> 83619.226 | AE39: =S39*$J39 -> 0 | AF39: =T39*$J39 -> 0 | AG39: =U39*$J39 -> 301149.67 | AH39: =V39*$J39 -> 0 | AI39: =W39*$J39 -> 0 | AJ39: =SUM(AE39:AI39) -> 301149.67 | AK39: =($P39*S39)*(1-$J39) -> 0 | AL39: =($P39*T39)*(1-$J39) -> 0 | AM39: =($P39*U39)*(1-$J39) -> 268776.08 | AN39: =($P39*V39)*(1-$J39) -> 0 | AO39: =($P39*W39)*(1-$J39) -> 0 | AP39: =SUM(AK39:AO39) -> 268776.08 | AQ39: =S39*$Q39 -> 0 | AR39: =T39*$Q39 -> 0 | AS39: =U39*$Q39 -> 60229.934 | AT39: =V39*$Q39 -> 0 | AU39: =W39*$Q39 -> 0 | AV39: =SUM(AQ39:AU39) -> 60229.934 | AW39: =S39*$R39 -> 0 | AX39: =T39*$R39 -> 0 | AY39: =U39*$R39 -> 80306.579 | AZ39: =V39*$R39 -> 0 | BA39: =W39*$R39 -> 0 | BB39: =SUM(AW39:BA39) -> 80306.579 | BC39: =$Y39+$AE39+$AK39+$AQ39+AW39 -> 0 | BD39: =$Z39+$AF39+$AL39+AR39+AX39 -> 0 | BE39: =$AA39+$AG39+$AM39+AS39+AY39 -> 794081.49 | BF39: =$AB39+$AH39+$AN39+AT39+AZ39 -> 0 | BG39: =$AC39+$AI39+$AO39+AU39+BA39 -> 0 | BH39: =SUM(BC39:BG39) -> 794081.49 | BI39: =$Y39/$M39 -> 0 | BJ39: =$Z39/$M39 -> 0 | BK39: =$AA39/$M39 -> 83619.226 | BL39: =$AB39/$M39 -> 0 | BM39: =$AC39/$M39 -> 0 | BN39: =$AD39/$M39 -> 83619.226 | BO39: =$AE39/$M39 -> 0 | BP39: =$AF39/$M39 -> 0 | BQ39: =$AG39/$M39 -> 301149.67 | BR39: =$AH39/$M39 -> 0 | BS39: =$AI39/$M39 -> 0 | BT39: =$AJ39/$M39 -> 301149.67 | BU39: =$AK39/$M39 -> 0 | BV39: =$AL39/$M39 -> 0 | BW39: =$AM39/$M39 -> 268776.08 | BX39: =$AN39/$M39 -> 0 | BY39: =$AO39/$M39 -> 0 | BZ39: =$AP39/$M39 -> 268776.08 | CA39: =AQ39/$M39 -> 0 | CB39: =AR39/$M39 -> 0 | CC39: =AS39/$M39 -> 60229.934 | CD39: =AT39/$M39 -> 0 | CE39: =AU39/$M39 -> 0 | CF39: =AV39/$M39 -> 60229.934 | CG39: =AW39/$M39 -> 0 | CH39: =AX39/$M39 -> 0 | ... CL39: =BB39/$M39 -> 80306.579 | CM39: =$BC39/$M39 -> 0 | CN39: =$BD39/$M39 -> 0 | CO39: =$BE39/$M39 -> 794081.49 | CP39: =$BF39/$M39 -> 0 | CQ39: =$BG39/$M39 -> 0 | CR39: =SUM(CM39:CQ39) -> 794081.49 | CS39: =K39-CR39 -> 1213583 | CU39: =D39 -> ARS | CV39: =VLOOKUP(CU39,DF:DG,2,0) -> 0.0006918517 | CW39: =K39*CV39 -> 1389.0061 | CX39: =BN39*CV39 -> 57.852103 | CY39: =BT39*CV39 -> 208.35091 | CZ39: =BZ39*CV39 -> 185.95319 | DA39: =CF39*CV39 -> 41.670183 | DB39: =CL39*CV39 -> 55.560243 | DC39: =CS39*CV39 -> 839.61945 | DD39: =VLOOKUP(A39,'Billing Report'!H:I,2,FALSE) -> 2025_MODO_BRANDING_PROMO_PROMO-DIAV2_TOTAL-PAIS_TWITTER_NU_AW_JUN-JUL | DF39: KRW | DG39: 0.0006930595
