Workbook

Sheet con 1
A1: Use your private filters OR Download file as Excel | AE1: Miss | AS1: Miss | BA1: Miss | BE1: =COLUMN((BE1)) -> 57 | CH1: =COLUMN(CH1) -> 86 | CI1: 46087.744
AE2: Incorrect | AS2: Incorrect | BA2: Incorrect | BG2: =er!A3 -> 46054 | CH2: Minutes until refresh: | CI2: =30-MINUTE(NOW()-CI1) -> 24
AF3: C3-Curr | AI3: C4-Diff | AK3: C5-Diff | AW3: C6-Curr | AX3: C7-Diff | BB3: C8-Curr | BC3: C9-Diff | CH3: Comment columns get hidden during the refresh.
A5: Account ID | B5: BU Name | C5: Division | D5: Structured Name | E5: SO Status | F5: PO Status | G5: Reporting Country | H5: Billing Entity | I5: Billing Country | J5: Revenue (Net Budget Delivered (Billing Currency)) | K5: Revenue (Net Budget Delivered (Billing Currency)) w/o deals | L5: Bill Curr | M5: Total Net Budget (Delivered) | N5: Account Curr | O5: Qualified Purch Qty | P5: Costs | Q5: Purch Curr | R5: Purch Country | S5: Deal Name | T5: Expected Discount % | U5: Real Discount % | V5: Year Month | W5: Posting Period | X5: Division | Y5: Quota Country | Z5: Purchase Country | AA5: Account Curr | AB5: Revenue | AC5: Purch Curr | AD5: Cost | AE5: Commision percentage | AF5: Purch Curr (SF-Bil) | AG5: Rev Dif (SF-Bil) | AH5: Rev Dif (SF-Bil) USD | AI5: Cost Dif (SF-Bil) | AJ5: Cost Dif (SF-Bil) USD | AK5: Margin (SF Rev-Cogs) | AL5: Purch Country (SF-Bil) | AM5: Invoice Number | AN5: Action Point | AO5: Bill To | AP5: Account Curr | AQ5: Account Spend Net | AR5: Purch Curr | AS5: Purch Spend Net | AT5: Account Curr (inv-SF) | AU5: Rev Dif (Inv - SF) | AV5: Rev Dif (Inv - SF) USD | AW5: Purch Curr (SF-Inv) | AX5: Cost Dif (SF-Inv) | AY5: Cost Dif (SF-Inv) USD | AZ5: Purch Curr | BA5: Spend Amount | BB5: Curr (SF-Stat) | BC5: Dif (SF-Stat) | BD5: Dif (SF-Stat) USD | BE5: Comm Percent | BF5: Comm Purch Curr | BG5: Comm USD Curr | BH5: Net Interco | BI5: Direct Tax Percent | BJ5: Direct Tax Purch Curr | BK5: Direct Tax USD Curr | BL5: With Tax Percent | BM5: With Tax Purch Curr | BN5: With Tax USD Curr | BO5: Fee | BP5: Fee Purch Curr | BQ5: Fee USD Curr | BR5: Direct Tax Percent | BS5: Direct Tax Purch Curr | BT5: Direct Tax USD Curr | BU5: With Tax Percent | BV5: With Tax Purch Curr | BW5: With Tax USD Curr | BX5: Fee | BY5: Fee Purch Curr | BZ5: Fee USD Curr | CA5: Margin SF Rev vs. SF Costs | CB5: Margin Bil Rev vs. Bil Costs | CC5: Margin SF - Margin Bil | CD5: Tax - Tax Bil | CE5: Tax - Tax Bil in USD | CF5: (Cost Dif (SF-Bil) USD) - (Tax - Tax Bil in USD) | CG5: Check (Comm Percent - Bil Commision percentage) | CH5: Comments for Operations | CI5: Comments for Rev&Cogs team | CK5: TAX AMMOUNT TWITTER | CL5: DIFF IN COGS WITHOUT TAX ERR | CN5: TAX AMMOUNT TWITTER USD
A6: T2694837 | B6: Twitter Rep | C6: IMS | D6: AR_Media Company_!Blocked Nessy LLC USA_AR00310258 TW - Lemon - US 2025 | G6: Argentina | H6: Aleph USA | I6: United States | J6: 902.75 | K6: 902.74894 | L6: USD | M6: 911867.62 | N6: ARS | O6: 911867.62 | P6: 711256.74 | Q6: ARS | R6: Mexico | U6: 0 | V6: 2026-02 | W6: February/2026 | X6: IMS | Y6: Argentina | Z6: Mexico | AA6: ARS | AB6: 911867.62 | AC6: ARS | AD6: 551201.18 | AE6: 39.55 | AF6: OK | AG6: 0 | AH6: 0 | AI6: 160055.56 | AJ6: 114.57 | AK6: 0.43602157 | AL6: OK | AM6: 10573708 | AO6: Miss | AP6: Miss | AR6: Miss | AT6: Miss | AU6: 911867.62 | AV6: 651 | AW6: Miss | AX6: 911867.62 | AY6: 652.73 | AZ6: ARS | BA6: 551201.18 | BB6: OK | BC6: 160055.56 | BD6: 114.57 | BE6: {=IFERROR(INDEX('Com&tax'!$E$2:$E$5, MATCH(1, ('Com&tax'!$A$2:$A$5=B6)*('Com&tax'!$B$2:$B$5=G6), 0)),"")} -> 0.15 | BF6: =IF(A6="","",( IFERROR(O6*BE6,""))) -> 136780.14 | BG6: {=IF(A6="","",( IFERROR((O6/ INDEX(er!$D$3:$D$75,MATCH(1, (er!$A$3:$A$75=$BG$2)*(er!$C$3:$C$75=Q6), 0)))*BE6,"")))} -> 97.909909 | BH6: =IF(A6="","",( IF(B6="Snapchat Rep", IF(A6="","",(P6-BF6)),-BF6))) -> -136780.14 | BI6: {=IFERROR(INDEX('Com&tax'!$F$2:$F$5, MATCH(1, ('Com&tax'!$A$2:$A$5=B6)*('Com&tax'!$B$2:$B$5=Y6), 0)),0)} -> 0.049 | BJ6: =IF(A6="","",( IFERROR((J6*(1-BE6))*BI6,0))) -> 37.599538 | BK6: {=IF(A6="","",( IFERROR((J6*(1-BE6))*BI6/INDEX(er!D:D, MATCH(Q6,er!C:C,0),1),0)))} -> 0.026914486 | BL6: {=IFERROR(INDEX('Com&tax'!$G$2:$G$5, MATCH(1, ('Com&tax'!$A$2:$A$5=B6)*('Com&tax'!$B$2:$B$5=Y6), 0)),0)} -> 0.1575 | BM6: =IF(A6="","",( IFERROR((J6*(1-BE6))*BL6,0))) -> 120.85566 | BN6: {=IF(A6="","",( IFERROR((J6*(1-BE6))*BL6/INDEX(er!D:D, MATCH(Q6,er!C:C,0),1),0)))} -> 0.086510849 | BO6: {=IFERROR(INDEX('Com&tax'!$H$2:$H$5, MATCH(1, ('Com&tax'!$A$2:$A$5=B6)*('Com&tax'!$B$2:$B$5=Y6), 0)),0)} -> 0.07 | BP6: =IF(A6="","",( IFERROR(J6*BO6,0))) -> 63.1925 | BQ6: {=IF(A6="","",( IFERROR(J6*BO6/INDEX(er!D:D, MATCH(Q6,er!C:C,0),1),0)))} -> 0.045234431 | BR6: {=IFERROR(INDEX('Com&tax'!$F$2:$F$5, MATCH(1, ('Com&tax'!$A$2:$A$5=B6)*('Com&tax'!$D$2:$D$5=H6), 0)),0)} -> 0 | BS6: =IF(A6="","",( IFERROR((J6*(1-BE6))*BR6,0))) -> 0 | BT6: {=IF(A6="","",( IFERROR((J6*(1-BE6))*BR6/INDEX(er!D:D, MATCH(Q6,er!C:C,0),1),0)))} -> 0 | BU6: {=IFERROR(INDEX('Com&tax'!$G$2:$G$5, MATCH(1, ('Com&tax'!$A$2:$A$5=B6)*('Com&tax'!$D$2:$D$5=H6), 0)),0)} -> 0 | BV6: =IF(A6="","",( IFERROR((J6*(1-BE6))*BU6,0))) -> 0 | BW6: {=IF(A6="","",( IFERROR((J6*(1-BE6))*BU6/INDEX(er!D:D, MATCH(Q6,er!C:C,0),1),0)))} -> 0 | BX6: {=IFERROR(INDEX('Com&tax'!$H$2:$H$5, MATCH(1, ('Com&tax'!$A$2:$A$5=B6)*('Com&tax'!$D$2:$D$5=H6), 0)),0)} -> 0 | BY6: =IF(A6="","",( IFERROR(J6*BX6,0))) -> 0 | BZ6: {=IF(A6="","",( IFERROR(J6*BX6/INDEX(er!D:D, MATCH(Q6,er!C:C,0),1),0)))} -> 0 | CA6: {=IF(A6="","",( IFERROR(1-((P6/ INDEX(er!$D$3:$D$75,MATCH(1, (er!$A$3:$A$75=$BG$2)*(er!$C$3:$C$75=Q6), 0)) / (J6/ INDEX(er!$D$3:$D$75,MATCH(1, (er!$A$3:$A$75=$BG$2)*(er!$C$3:$C$75=L6), 0))))),"")))} -> 0.43602157 | CB6: =IF(AB6="","",1-AD6/AB6) -> 0.395525 | CC6: =IF(AND(CA6="", CB6=""), "", CA6-CB6) -> 0.040496574 | CD6: =BJ6+BM6-BS6-BV6 -> 158.45519 | CE6: =BK6+BN6-BT6-BW6 -> 0.11342534 | CF6: =AJ6-CE6 -> 114.45657 | CG6: =IF(OR(BE6="", AE6=""), "Miss", IF(ABS(AE6/100-AK6)<0.005, "OK", "Incorrect")) -> Incorrect | CI6: OK. Diff. Bill. / Adv. Country | CK6: 0 | CL6: =(AI6+CK6)/INDEX(er!D:D,MATCH(AC6,er!C:C,0),1) -> 114.57091 | CN6: =CK6/INDEX(er!D:D,MATCH(AC6,er!C:C,0),1) -> 0
A7: T2751490 | B7: Twitter Rep | C7: IMS | D7: AR_Media Company_BANCO DE LA PROVINCIA DE CORDOBA ARGENTINA_SMB-X ARG - Banco de Cordoba - Ene - abril 24 UPSELL 5 | G7: Argentina | H7: Aleph Argentina | I7: Argentina | J7: 3855555.8 | K7: 3855555.8 | L7: ARS | M7: 3855555.8 | N7: ARS | O7: 3855555.8 | P7: 2330587.2 | Q7: ARS | R7: Mexico | U7: 0 | V7: 2026-02 | W7: February/2026 | X7: IMS | Y7: Argentina | Z7: Mexico | AA7: ARS | AB7: 3855555.8 | AC7: ARS | AD7: 2330587.1 | AE7: 39.55 | AF7: OK | AG7: 0 | AH7: 0 | AI7: 0.15 | AJ7: 0 | AK7: 0.39552496 | AL7: OK | AM7: 10573709 | AO7: Miss | AP7: Miss | AR7: Miss | AT7: Miss | AU7: 3855555.8 | AV7: 2758 | AW7: Miss | AX7: 3855555.8 | AY7: 2759.88 | AZ7: ARS | BA7: 2330587.1 | BB7: OK | BC7: 0.16 | BD7: 0 | BE7: {=IFERROR(INDEX('Com&tax'!$E$2:$E$5, MATCH(1, ('Com&tax'!$A$2:$A$5=B7)*('Com&tax'!$B$2:$B$5=G7), 0)),"")} -> 0.15 | BF7: =IF(A7="","",( IFERROR(O7*BE7,""))) -> 578333.37 | BG7: {=IF(A7="","",( IFERROR((O7/ INDEX(er!$D$3:$D$75,MATCH(1, (er!$A$3:$A$75=$BG$2)*(er!$C$3:$C$75=Q7), 0)))*BE7,"")))} -> 413.98237 | BH7: =IF(A7="","",( IF(B7="Snapchat Rep", IF(A7="","",(P7-BF7)),-BF7))) -> -578333.37 | BI7: {=IFERROR(INDEX('Com&tax'!$F$2:$F$5, MATCH(1, ('Com&tax'!$A$2:$A$5=B7)*('Com&tax'!$B$2:$B$5=Y7), 0)),0)} -> 0.049 | BJ7: =IF(A7="","",( IFERROR((J7*(1-BE7))*BI7,0))) -> 160583.9 | BK7: {=IF(A7="","",( IFERROR((J7*(1-BE7))*BI7/INDEX(er!D:D, MATCH(Q7,er!C:C,0),1),0)))} -> 114.9491 | BL7: {=IFERROR(INDEX('Com&tax'!$G$2:$G$5, MATCH(1, ('Com&tax'!$A$2:$A$5=B7)*('Com&tax'!$B$2:$B$5=Y7), 0)),0)} -> 0.1575 | BM7: =IF(A7="","",( IFERROR((J7*(1-BE7))*BL7,0))) -> 516162.53 | BN7: {=IF(A7="","",( IFERROR((J7*(1-BE7))*BL7/INDEX(er!D:D, MATCH(Q7,er!C:C,0),1),0)))} -> 369.47926 | BO7: {=IFERROR(INDEX('Com&tax'!$H$2:$H$5, MATCH(1, ('Com&tax'!$A$2:$A$5=B7)*('Com&tax'!$B$2:$B$5=Y7), 0)),0)} -> 0.07 | BP7: =IF(A7="","",( IFERROR(J7*BO7,0))) -> 269888.91 | BQ7: {=IF(A7="","",( IFERROR(J7*BO7/INDEX(er!D:D, MATCH(Q7,er!C:C,0),1),0)))} -> 193.19177 | BR7: {=IFERROR(INDEX('Com&tax'!$F$2:$F$5, MATCH(1, ('Com&tax'!$A$2:$A$5=B7)*('Com&tax'!$D$2:$D$5=H7), 0)),0)} -> 0.049 | BS7: =IF(A7="","",( IFERROR((J7*(1-BE7))*BR7,0))) -> 160583.9 | BT7: {=IF(A7="","",( IFERROR((J7*(1-BE7))*BR7/INDEX(er!D:D, MATCH(Q7,er!C:C,0),1),0)))} -> 114.9491 | BU7: {=IFERROR(INDEX('Com&tax'!$G$2:$G$5, MATCH(1, ('Com&tax'!$A$2:$A$5=B7)*('Com&tax'!$D$2:$D$5=H7), 0)),0)} -> 0.1575 | BV7: =IF(A7="","",( IFERROR((J7*(1-BE7))*BU7,0))) -> 516162.53 | BW7: {=IF(A7="","",( IFERROR((J7*(1-BE7))*BU7/INDEX(er!D:D, MATCH(Q7,er!C:C,0),1),0)))} -> 369.47926 | BX7: {=IFERROR(INDEX('Com&tax'!$H$2:$H$5, MATCH(1, ('Com&tax'!$A$2:$A$5=B7)*('Com&tax'!$D$2:$D$5=H7), 0)),0)} -> 0.07 | BY7: =IF(A7="","",( IFERROR(J7*BX7,0))) -> 269888.91 | BZ7: {=IF(A7="","",( IFERROR(J7*BX7/INDEX(er!D:D, MATCH(Q7,er!C:C,0),1),0)))} -> 193.19177 | CA7: {=IF(A7="","",( IFERROR(1-((P7/ INDEX(er!$D$3:$D$75,MATCH(1, (er!$A$3:$A$75=$BG$2)*(er!$C$3:$C$75=Q7), 0)) / (J7/ INDEX(er!$D$3:$D$75,MATCH(1, (er!$A$3:$A$75=$BG$2)*(er!$C$3:$C$75=L7), 0))))),"")))} -> 0.39552496 | CB7: =IF(AB7="","",1-AD7/AB7) -> 0.395525 | CC7: =IF(AND(CA7="", CB7=""), "", CA7-CB7) -> -3.8904897e-08 | CD7: =BJ7+BM7-BS7-BV7 -> 0 | CE7: =BK7+BN7-BT7-BW7 -> 0 | CF7: =AJ7-CE7 -> 0 | CG7: =IF(OR(BE7="", AE7=""), "Miss", IF(ABS(AE7/100-AK7)<0.005, "OK", "Incorrect")) -> OK | CI7: OK | CK7: 0 | CL7: =(AI7+CK7)/INDEX(er!D:D,MATCH(AC7,er!C:C,0),1) -> 0.00010737294 | CN7: =CK7/INDEX(er!D:D,MATCH(AC7,er!C:C,0),1) -> 0
A8: T2767832 | B8: Twitter Rep | C8: IMS | D8: AR_Media Company_Almundo.com SRL_X - almundo- 2025 | G8: Argentina | H8: Aleph Argentina | I8: Argentina | J8: 3113913.1 | K8: 3113913.1 | L8: ARS | M8: 3113913.1 | N8: ARS | O8: 3113913.1 | P8: 1882282.7 | Q8: ARS | R8: Mexico | U8: 0 | V8: 2026-02 | W8: February/2026 | X8: IMS | Y8: Argentina | Z8: Mexico | AA8: ARS | AB8: 3113913.1 | AC8: ARS | AD8: 1882282.6 | AE8: 39.55 | AF8: OK | AG8: 0 | AH8: 0 | AI8: 0.12 | AJ8: 0 | AK8: 0.39552496 | AL8: OK | AM8: 10573710 | AO8: Miss | AP8: Miss | AR8: Miss | AT8: Miss | AU8: 3113913.1 | AV8: 2227 | AW8: Miss | AX8: 3113913.1 | AY8: 2229 | AZ8: ARS | BA8: 1882282.6 | BB8: OK | BC8: 0.12 | BD8: 0 | BE8: {=IFERROR(INDEX('Com&tax'!$E$2:$E$5, MATCH(1, ('Com&tax'!$A$2:$A$5=B8)*('Com&tax'!$B$2:$B$5=G8), 0)),"")} -> 0.15 | BF8: =IF(A8="","",( IFERROR(O8*BE8,""))) -> 467086.96 | BG8: {=IF(A8="","",( IFERROR((O8/ INDEX(er!$D$3:$D$75,MATCH(1, (er!$A$3:$A$75=$BG$2)*(er!$C$3:$C$75=Q8), 0)))*BE8,"")))} -> 334.35001 | BH8: =IF(A8="","",( IF(B8="Snapchat Rep", IF(A8="","",(P8-BF8)),-BF8))) -> -467086.96 | BI8: {=IFERROR(INDEX('Com&tax'!$F$2:$F$5, MATCH(1, ('Com&tax'!$A$2:$A$5=B8)*('Com&tax'!$B$2:$B$5=Y8), 0)),0)} -> 0.049 | BJ8: =IF(A8="","",( IFERROR((J8*(1-BE8))*BI8,0))) -> 129694.48 | BK8: {=IF(A8="","",( IFERROR((J8*(1-BE8))*BI8/INDEX(er!D:D, MATCH(Q8,er!C:C,0),1),0)))} -> 92.837852 | BL8: {=IFERROR(INDEX('Com&tax'!$G$2:$G$5, MATCH(1, ('Com&tax'!$A$2:$A$5=B8)*('Com&tax'!$B$2:$B$5=Y8), 0)),0)} -> 0.1575 | BM8: =IF(A8="","",( IFERROR((J8*(1-BE8))*BL8,0))) -> 416875.11 | BN8: {=IF(A8="","",( IFERROR((J8*(1-BE8))*BL8/INDEX(er!D:D, MATCH(Q8,er!C:C,0),1),0)))} -> 298.40738 | BO8: {=IFERROR(INDEX('Com&tax'!$H$2:$H$5, MATCH(1, ('Com&tax'!$A$2:$A$5=B8)*('Com&tax'!$B$2:$B$5=Y8), 0)),0)} -> 0.07 | BP8: =IF(A8="","",( IFERROR(J8*BO8,0))) -> 217973.92 | BQ8: {=IF(A8="","",( IFERROR(J8*BO8/INDEX(er!D:D, MATCH(Q8,er!C:C,0),1),0)))} -> 156.03 | BR8: {=IFERROR(INDEX('Com&tax'!$F$2:$F$5, MATCH(1, ('Com&tax'!$A$2:$A$5=B8)*('Com&tax'!$D$2:$D$5=H8), 0)),0)} -> 0.049 | BS8: =IF(A8="","",( IFERROR((J8*(1-BE8))*BR8,0))) -> 129694.48 | BT8: {=IF(A8="","",( IFERROR((J8*(1-BE8))*BR8/INDEX(er!D:D, MATCH(Q8,er!C:C,0),1),0)))} -> 92.837852 | BU8: {=IFERROR(INDEX('Com&tax'!$G$2:$G$5, MATCH(1, ('Com&tax'!$A$2:$A$5=B8)*('Com&tax'!$D$2:$D$5=H8), 0)),0)} -> 0.1575 | BV8: =IF(A8="","",( IFERROR((J8*(1-BE8))*BU8,0))) -> 416875.11 | BW8: {=IF(A8="","",( IFERROR((J8*(1-BE8))*BU8/INDEX(er!D:D, MATCH(Q8,er!C:C,0),1),0)))} -> 298.40738 | BX8: {=IFERROR(INDEX('Com&tax'!$H$2:$H$5, MATCH(1, ('Com&tax'!$A$2:$A$5=B8)*('Com&tax'!$D$2:$D$5=H8), 0)),0)} -> 0.07 | BY8: =IF(A8="","",( IFERROR(J8*BX8,0))) -> 217973.92 | BZ8: {=IF(A8="","",( IFERROR(J8*BX8/INDEX(er!D:D, MATCH(Q8,er!C:C,0),1),0)))} -> 156.03 | CA8: {=IF(A8="","",( IFERROR(1-((P8/ INDEX(er!$D$3:$D$75,MATCH(1, (er!$A$3:$A$75=$BG$2)*(er!$C$3:$C$75=Q8), 0)) / (J8/ INDEX(er!$D$3:$D$75,MATCH(1, (er!$A$3:$A$75=$BG$2)*(er!$C$3:$C$75=L8), 0))))),"")))} -> 0.39552496 | CB8: =IF(AB8="","",1-AD8/AB8) -> 0.395525 | CC8: =IF(AND(CA8="", CB8=""), "", CA8-CB8) -> -3.8536721e-08 | CD8: =BJ8+BM8-BS8-BV8 -> 0 | CE8: =BK8+BN8-BT8-BW8 -> 0 | CF8: =AJ8-CE8 -> 0 | CG8: =IF(OR(BE8="", AE8=""), "Miss", IF(ABS(AE8/100-AK8)<0.005, "OK", "Incorrect")) -> OK | CI8: OK | CK8: 0 | CL8: =(AI8+CK8)/INDEX(er!D:D,MATCH(AC8,er!C:C,0),1) -> 8.5898354e-05 | CN8: =CK8/INDEX(er!D:D,MATCH(AC8,er!C:C,0),1) -> 0
A9: T2834460 | B9: Twitter Rep | C9: IMS | D9: AR_Media Company_Flybondi_SMB-X ARG - Flybondi (may - jun 24) | G9: Argentina | H9: Aleph Argentina | I9: Argentina | J9: 2687841.5 | K9: 2687841.5 | L9: ARS | M9: 2687841.5 | N9: ARS | O9: 2687841.5 | P9: 1624733.1 | Q9: ARS | R9: Mexico | U9: 0 | V9: 2026-02 | W9: February/2026 | X9: IMS | Y9: Argentina | Z9: Mexico | AA9: ARS | AB9: 2687841.5 | AC9: ARS | AD9: 1624733 | AE9: 39.55 | AF9: OK | AG9: 0 | AH9: 0 | AI9: 0.1 | AJ9: 0 | AK9: 0.39552496 | AL9: OK | AM9: 10573711 | AO9: Miss | AP9: Miss | AR9: Miss | AT9: Miss | AU9: 2687841.5 | AV9: 1922 | AW9: Miss | AX9: 2687841.5 | AY9: 1924.01 | AZ9: ARS | BA9: 1624733 | BB9: OK | BC9: 0.11 | BD9: 0 | BE9: {=IFERROR(INDEX('Com&tax'!$E$2:$E$5, MATCH(1, ('Com&tax'!$A$2:$A$5=B9)*('Com&tax'!$B$2:$B$5=G9), 0)),"")} -> 0.15 | BF9: =IF(A9="","",( IFERROR(O9*BE9,""))) -> 403176.22 | BG9: {=IF(A9="","",( IFERROR((O9/ INDEX(er!$D$3:$D$75,MATCH(1, (er!$A$3:$A$75=$BG$2)*(er!$C$3:$C$75=Q9), 0)))*BE9,"")))} -> 288.60145 | BH9: =IF(A9="","",( IF(B9="Snapchat Rep", IF(A9="","",(P9-BF9)),-BF9))) -> -403176.22 | BI9: {=IFERROR(INDEX('Com&tax'!$F$2:$F$5, MATCH(1, ('Com&tax'!$A$2:$A$5=B9)*('Com&tax'!$B$2:$B$5=Y9), 0)),0)} -> 0.049 | BJ9: =IF(A9="","",( IFERROR((J9*(1-BE9))*BI9,0))) -> 111948.6 | BK9: {=IF(A9="","",( IFERROR((J9*(1-BE9))*BI9/INDEX(er!D:D, MATCH(Q9,er!C:C,0),1),0)))} -> 80.135001 | BL9: {=IFERROR(INDEX('Com&tax'!$G$2:$G$5, MATCH(1, ('Com&tax'!$A$2:$A$5=B9)*('Com&tax'!$B$2:$B$5=Y9), 0)),0)} -> 0.1575 | BM9: =IF(A9="","",( IFERROR((J9*(1-BE9))*BL9,0))) -> 359834.78 | BN9: {=IF(A9="","",( IFERROR((J9*(1-BE9))*BL9/INDEX(er!D:D, MATCH(Q9,er!C:C,0),1),0)))} -> 257.57679 | BO9: {=IFERROR(INDEX('Com&tax'!$H$2:$H$5, MATCH(1, ('Com&tax'!$A$2:$A$5=B9)*('Com&tax'!$B$2:$B$5=Y9), 0)),0)} -> 0.07 | BP9: =IF(A9="","",( IFERROR(J9*BO9,0))) -> 188148.9 | BQ9: {=IF(A9="","",( IFERROR(J9*BO9/INDEX(er!D:D, MATCH(Q9,er!C:C,0),1),0)))} -> 134.68067 | BR9: {=IFERROR(INDEX('Com&tax'!$F$2:$F$5, MATCH(1, ('Com&tax'!$A$2:$A$5=B9)*('Com&tax'!$D$2:$D$5=H9), 0)),0)} -> 0.049 | BS9: =IF(A9="","",( IFERROR((J9*(1-BE9))*BR9,0))) -> 111948.6 | BT9: {=IF(A9="","",( IFERROR((J9*(1-BE9))*BR9/INDEX(er!D:D, MATCH(Q9,er!C:C,0),1),0)))} -> 80.135001 | BU9: {=IFERROR(INDEX('Com&tax'!$G$2:$G$5, MATCH(1, ('Com&tax'!$A$2:$A$5=B9)*('Com&tax'!$D$2:$D$5=H9), 0)),0)} -> 0.1575 | BV9: =IF(A9="","",( IFERROR((J9*(1-BE9))*BU9,0))) -> 359834.78 | BW9: {=IF(A9="","",( IFERROR((J9*(1-BE9))*BU9/INDEX(er!D:D, MATCH(Q9,er!C:C,0),1),0)))} -> 257.57679 | BX9: {=IFERROR(INDEX('Com&tax'!$H$2:$H$5, MATCH(1, ('Com&tax'!$A$2:$A$5=B9)*('Com&tax'!$D$2:$D$5=H9), 0)),0)} -> 0.07 | BY9: =IF(A9="","",( IFERROR(J9*BX9,0))) -> 188148.9 | BZ9: {=IF(A9="","",( IFERROR(J9*BX9/INDEX(er!D:D, MATCH(Q9,er!C:C,0),1),0)))} -> 134.68067 | CA9: {=IF(A9="","",( IFERROR(1-((P9/ INDEX(er!$D$3:$D$75,MATCH(1, (er!$A$3:$A$75=$BG$2)*(er!$C$3:$C$75=Q9), 0)) / (J9/ INDEX(er!$D$3:$D$75,MATCH(1, (er!$A$3:$A$75=$BG$2)*(er!$C$3:$C$75=L9), 0))))),"")))} -> 0.39552496 | CB9: =IF(AB9="","",1-AD9/AB9) -> 0.395525 | CC9: =IF(AND(CA9="", CB9=""), "", CA9-CB9) -> -3.7204575e-08 | CD9: =BJ9+BM9-BS9-BV9 -> 0 | CE9: =BK9+BN9-BT9-BW9 -> 0 | CF9: =AJ9-CE9 -> 0 | CG9: =IF(OR(BE9="", AE9=""), "Miss", IF(ABS(AE9/100-AK9)<0.005, "OK", "Incorrect")) -> OK | CI9: OK | CK9: 0 | CL9: =(AI9+CK9)/INDEX(er!D:D,MATCH(AC9,er!C:C,0),1) -> 7.1581961e-05 | CN9: =CK9/INDEX(er!D:D,MATCH(AC9,er!C:C,0),1) -> 0
A10: T2887099 | B10: Twitter Rep | C10: IMS | D10: AR_Media Company_FINTECH Argentina_TW - Satoshi Tango - Q3 | G10: Argentina | H10: Aleph Argentina | I10: Argentina | J10: 1055530.2 | K10: 1055530.2 | L10: ARS | M10: 1055530.2 | N10: ARS | O10: 1055530.2 | P10: 638041.67 | Q10: ARS | R10: Mexico | U10: 0 | V10: 2026-02 | W10: February/2026 | X10: IMS | Y10: Argentina | Z10: Mexico | AA10: ARS | AB10: 1055530.2 | AC10: ARS | AD10: 638041.63 | AE10: 39.55 | AF10: OK | AG10: 0 | AH10: 0 | AI10: 0.04 | AJ10: 0 | AK10: 0.39552496 | AL10: OK | AM10: 10573707 | AO10: Miss | AP10: Miss | AR10: Miss | AT10: Miss | AU10: 1055530.2 | AV10: 754 | AW10: Miss | AX10: 1055530.2 | AY10: 755.57 | AZ10: ARS | BA10: 638041.62 | BB10: OK | BC10: 0.05 | BD10: 0 | BE10: {=IFERROR(INDEX('Com&tax'!$E$2:$E$5, MATCH(1, ('Com&tax'!$A$2:$A$5=B10)*('Com&tax'!$B$2:$B$5=G10), 0)),"")} -> 0.15 | BF10: =IF(A10="","",( IFERROR(O10*BE10,""))) -> 158329.53 | BG10: {=IF(A10="","",( IFERROR((O10/ INDEX(er!$D$3:$D$75,MATCH(1, (er!$A$3:$A$75=$BG$2)*(er!$C$3:$C$75=Q10), 0)))*BE10,"")))} -> 113.33538 | BH10: =IF(A10="","",( IF(B10="Snapchat Rep", IF(A10="","",(P10-BF10)),-BF10))) -> -158329.53 | BI10: {=IFERROR(INDEX('Com&tax'!$F$2:$F$5, MATCH(1, ('Com&tax'!$A$2:$A$5=B10)*('Com&tax'!$B$2:$B$5=Y10), 0)),0)} -> 0.049 | BJ10: =IF(A10="","",( IFERROR((J10*(1-BE10))*BI10,0))) -> 43962.833 | BK10: {=IF(A10="","",( IFERROR((J10*(1-BE10))*BI10/INDEX(er!D:D, MATCH(Q10,er!C:C,0),1),0)))} -> 31.469458 | BL10: {=IFERROR(INDEX('Com&tax'!$G$2:$G$5, MATCH(1, ('Com&tax'!$A$2:$A$5=B10)*('Com&tax'!$B$2:$B$5=Y10), 0)),0)} -> 0.1575 | BM10: =IF(A10="","",( IFERROR((J10*(1-BE10))*BL10,0))) -> 141309.11 | BN10: {=IF(A10="","",( IFERROR((J10*(1-BE10))*BL10/INDEX(er!D:D, MATCH(Q10,er!C:C,0),1),0)))} -> 101.15183 | BO10: {=IFERROR(INDEX('Com&tax'!$H$2:$H$5, MATCH(1, ('Com&tax'!$A$2:$A$5=B10)*('Com&tax'!$B$2:$B$5=Y10), 0)),0)} -> 0.07 | BP10: =IF(A10="","",( IFERROR(J10*BO10,0))) -> 73887.115 | BQ10: {=IF(A10="","",( IFERROR(J10*BO10/INDEX(er!D:D, MATCH(Q10,er!C:C,0),1),0)))} -> 52.889846 | BR10: {=IFERROR(INDEX('Com&tax'!$F$2:$F$5, MATCH(1, ('Com&tax'!$A$2:$A$5=B10)*('Com&tax'!$D$2:$D$5=H10), 0)),0)} -> 0.049 | BS10: =IF(A10="","",( IFERROR((J10*(1-BE10))*BR10,0))) -> 43962.833 | BT10: {=IF(A10="","",( IFERROR((J10*(1-BE10))*BR10/INDEX(er!D:D, MATCH(Q10,er!C:C,0),1),0)))} -> 31.469458 | BU10: {=IFERROR(INDEX('Com&tax'!$G$2:$G$5, MATCH(1, ('Com&tax'!$A$2:$A$5=B10)*('Com&tax'!$D$2:$D$5=H10), 0)),0)} -> 0.1575 | BV10: =IF(A10="","",( IFERROR((J10*(1-BE10))*BU10,0))) -> 141309.11 | BW10: {=IF(A10="","",( IFERROR((J10*(1-BE10))*BU10/INDEX(er!D:D, MATCH(Q10,er!C:C,0),1),0)))} -> 101.15183 | BX10: {=IFERROR(INDEX('Com&tax'!$H$2:$H$5, MATCH(1, ('Com&tax'!$A$2:$A$5=B10)*('Com&tax'!$D$2:$D$5=H10), 0)),0)} -> 0.07 | BY10: =IF(A10="","",( IFERROR(J10*BX10,0))) -> 73887.115 | BZ10: {=IF(A10="","",( IFERROR(J10*BX10/INDEX(er!D:D, MATCH(Q10,er!C:C,0),1),0)))} -> 52.889846 | CA10: {=IF(A10="","",( IFERROR(1-((P10/ INDEX(er!$D$3:$D$75,MATCH(1, (er!$A$3:$A$75=$BG$2)*(er!$C$3:$C$75=Q10), 0)) / (J10/ INDEX(er!$D$3:$D$75,MATCH(1, (er!$A$3:$A$75=$BG$2)*(er!$C$3:$C$75=L10), 0))))),"")))} -> 0.39552496 | CB10: =IF(AB10="","",1-AD10/AB10) -> 0.39552499 | CC10: =IF(AND(CA10="", CB10=""), "", CA10-CB10) -> -3.7895647e-08 | CD10: =BJ10+BM10-BS10-BV10 -> 0 | CE10: =BK10+BN10-BT10-BW10 -> 0 | CF10: =AJ10-CE10 -> 0 | CG10: =IF(OR(BE10="", AE10=""), "Miss", IF(ABS(AE10/100-AK10)<0.005, "OK", "Incorrect")) -> OK | CI10: OK | CK10: 0 | CL10: =(AI10+CK10)/INDEX(er!D:D,MATCH(AC10,er!C:C,0),1) -> 2.8632785e-05 | CN10: =CK10/INDEX(er!D:D,MATCH(AC10,er!C:C,0),1) -> 0
A11: T2929648 | B11: Twitter Rep | C11: IMS | D11: AR_Media Company_Liliana SRL_SMB-X ARG - Liliana - Octubre 24 | G11: Argentina | H11: Aleph Argentina | I11: Argentina | J11: 1269863.2 | K11: 1269863.2 | L11: ARS | M11: 1269863.2 | N11: ARS | O11: 1269863.2 | P11: 767600.62 | Q11: ARS | R11: Mexico | U11: 0 | V11: 2026-02 | W11: February/2026 | X11: IMS | Y11: Argentina | Z11: Mexico | AA11: ARS | AB11: 1269863.2 | AC11: ARS | AD11: 767600.57 | AE11: 39.55 | AF11: OK | AG11: 0 | AH11: 0 | AI11: 0.05 | AJ11: 0 | AK11: 0.39552496 | AL11: OK | AM11: 10573619 | AO11: Miss | AP11: Miss | AR11: Miss | AT11: Miss | AU11: 1269863.2 | AV11: 907 | AW11: Miss | AX11: 1269863.2 | AY11: 908.99 | AZ11: ARS | BA11: 767600.57 | BB11: OK | BC11: 0.05 | BD11: 0 | BE11: {=IFERROR(INDEX('Com&tax'!$E$2:$E$5, MATCH(1, ('Com&tax'!$A$2:$A$5=B11)*('Com&tax'!$B$2:$B$5=G11), 0)),"")} -> 0.15 | BF11: =IF(A11="","",( IFERROR(O11*BE11,""))) -> 190479.48 | BG11: {=IF(A11="","",( IFERROR((O11/ INDEX(er!$D$3:$D$75,MATCH(1, (er!$A$3:$A$75=$BG$2)*(er!$C$3:$C$75=Q11), 0)))*BE11,"")))} -> 136.34895 | BH11: =IF(A11="","",( IF(B11="Snapchat Rep", IF(A11="","",(P11-BF11)),-BF11))) -> -190479.48 | BI11: {=IFERROR(INDEX('Com&tax'!$F$2:$F$5, MATCH(1, ('Com&tax'!$A$2:$A$5=B11)*('Com&tax'!$B$2:$B$5=Y11), 0)),0)} -> 0.049 | BJ11: =IF(A11="","",( IFERROR((J11*(1-BE11))*BI11,0))) -> 52889.803 | BK11: {=IF(A11="","",( IFERROR((J11*(1-BE11))*BI11/INDEX(er!D:D, MATCH(Q11,er!C:C,0),1),0)))} -> 37.859558 | BL11: {=IFERROR(INDEX('Com&tax'!$G$2:$G$5, MATCH(1, ('Com&tax'!$A$2:$A$5=B11)*('Com&tax'!$B$2:$B$5=Y11), 0)),0)} -> 0.1575 | BM11: =IF(A11="","",( IFERROR((J11*(1-BE11))*BL11,0))) -> 170002.94 | BN11: {=IF(A11="","",( IFERROR((J11*(1-BE11))*BL11/INDEX(er!D:D, MATCH(Q11,er!C:C,0),1),0)))} -> 121.69144 | BO11: {=IFERROR(INDEX('Com&tax'!$H$2:$H$5, MATCH(1, ('Com&tax'!$A$2:$A$5=B11)*('Com&tax'!$B$2:$B$5=Y11), 0)),0)} -> 0.07 | BP11: =IF(A11="","",( IFERROR(J11*BO11,0))) -> 88890.425 | BQ11: {=IF(A11="","",( IFERROR(J11*BO11/INDEX(er!D:D, MATCH(Q11,er!C:C,0),1),0)))} -> 63.62951 | BR11: {=IFERROR(INDEX('Com&tax'!$F$2:$F$5, MATCH(1, ('Com&tax'!$A$2:$A$5=B11)*('Com&tax'!$D$2:$D$5=H11), 0)),0)} -> 0.049 | BS11: =IF(A11="","",( IFERROR((J11*(1-BE11))*BR11,0))) -> 52889.803 | BT11: {=IF(A11="","",( IFERROR((J11*(1-BE11))*BR11/INDEX(er!D:D, MATCH(Q11,er!C:C,0),1),0)))} -> 37.859558 | BU11: {=IFERROR(INDEX('Com&tax'!$G$2:$G$5, MATCH(1, ('Com&tax'!$A$2:$A$5=B11)*('Com&tax'!$D$2:$D$5=H11), 0)),0)} -> 0.1575 | BV11: =IF(A11="","",( IFERROR((J11*(1-BE11))*BU11,0))) -> 170002.94 | BW11: {=IF(A11="","",( IFERROR((J11*(1-BE11))*BU11/INDEX(er!D:D, MATCH(Q11,er!C:C,0),1),0)))} -> 121.69144 | BX11: {=IFERROR(INDEX('Com&tax'!$H$2:$H$5, MATCH(1, ('Com&tax'!$A$2:$A$5=B11)*('Com&tax'!$D$2:$D$5=H11), 0)),0)} -> 0.07 | BY11: =IF(A11="","",( IFERROR(J11*BX11,0))) -> 88890.425 | BZ11: {=IF(A11="","",( IFERROR(J11*BX11/INDEX(er!D:D, MATCH(Q11,er!C:C,0),1),0)))} -> 63.62951 | CA11: {=IF(A11="","",( IFERROR(1-((P11/ INDEX(er!$D$3:$D$75,MATCH(1, (er!$A$3:$A$75=$BG$2)*(er!$C$3:$C$75=Q11), 0)) / (J11/ INDEX(er!$D$3:$D$75,MATCH(1, (er!$A$3:$A$75=$BG$2)*(er!$C$3:$C$75=L11), 0))))),"")))} -> 0.39552496 | CB11: =IF(AB11="","",1-AD11/AB11) -> 0.395525 | CC11: =IF(AND(CA11="", CB11=""), "", CA11-CB11) -> -3.9374319e-08 | CD11: =BJ11+BM11-BS11-BV11 -> 0 | CE11: =BK11+BN11-BT11-BW11 -> 0 | CF11: =AJ11-CE11 -> 0 | CG11: =IF(OR(BE11="", AE11=""), "Miss", IF(ABS(AE11/100-AK11)<0.005, "OK", "Incorrect")) -> OK | CI11: OK | CK11: 0 | CL11: =(AI11+CK11)/INDEX(er!D:D,MATCH(AC11,er!C:C,0),1) -> 3.5790981e-05 | CN11: =CK11/INDEX(er!D:D,MATCH(AC11,er!C:C,0),1) -> 0
A12: T2985381 | B12: Twitter Rep | C12: IMS | D12: AR_Media Company_Cocos Capital Argentina_AR00303899 | X | Cocos Cap | ENE 26 | G12: Argentina | H12: Aleph Argentina | I12: Argentina | J12: 1900327.9 | K12: 1900327.9 | L12: ARS | M12: 1900327.9 | N12: ARS | O12: 1900327.9 | P12: 1148700.8 | Q12: ARS | R12: Mexico | U12: 0 | V12: 2026-02 | W12: February/2026 | X12: IMS | Y12: Argentina | Z12: Mexico | AA12: ARS | AB12: 1900327.9 | AC12: ARS | AD12: 1148700.7 | AE12: 39.55 | AF12: OK | AG12: 0 | AH12: 0 | AI12: 0.07 | AJ12: 0 | AK12: 0.39552496 | AL12: OK | AM12: 10573629 | AO12: Miss | AP12: Miss | AR12: Miss | AT12: Miss | AU12: 1900327.9 | AV12: 1358 | AW12: Miss | AX12: 1900327.9 | AY12: 1360.29 | AZ12: ARS | BA12: 1148700.7 | BB12: OK | BC12: 0.08 | BD12: 0 | BE12: {=IFERROR(INDEX('Com&tax'!$E$2:$E$5, MATCH(1, ('Com&tax'!$A$2:$A$5=B12)*('Com&tax'!$B$2:$B$5=G12), 0)),"")} -> 0.15 | BF12: =IF(A12="","",( IFERROR(O12*BE12,""))) -> 285049.19 | BG12: {=IF(A12="","",( IFERROR((O12/ INDEX(er!$D$3:$D$75,MATCH(1, (er!$A$3:$A$75=$BG$2)*(er!$C$3:$C$75=Q12), 0)))*BE12,"")))} -> 204.0438 | BH12: =IF(A12="","",( IF(B12="Snapchat Rep", IF(A12="","",(P12-BF12)),-BF12))) -> -285049.19 | BI12: {=IFERROR(INDEX('Com&tax'!$F$2:$F$5, MATCH(1, ('Com&tax'!$A$2:$A$5=B12)*('Com&tax'!$B$2:$B$5=Y12), 0)),0)} -> 0.049 | BJ12: =IF(A12="","",( IFERROR((J12*(1-BE12))*BI12,0))) -> 79148.659 | BK12: {=IF(A12="","",( IFERROR((J12*(1-BE12))*BI12/INDEX(er!D:D, MATCH(Q12,er!C:C,0),1),0)))} -> 56.656163 | BL12: {=IFERROR(INDEX('Com&tax'!$G$2:$G$5, MATCH(1, ('Com&tax'!$A$2:$A$5=B12)*('Com&tax'!$B$2:$B$5=Y12), 0)),0)} -> 0.1575 | BM12: =IF(A12="","",( IFERROR((J12*(1-BE12))*BL12,0))) -> 254406.4 | BN12: {=IF(A12="","",( IFERROR((J12*(1-BE12))*BL12/INDEX(er!D:D, MATCH(Q12,er!C:C,0),1),0)))} -> 182.10909 | BO12: {=IFERROR(INDEX('Com&tax'!$H$2:$H$5, MATCH(1, ('Com&tax'!$A$2:$A$5=B12)*('Com&tax'!$B$2:$B$5=Y12), 0)),0)} -> 0.07 | BP12: =IF(A12="","",( IFERROR(J12*BO12,0))) -> 133022.96 | BQ12: {=IF(A12="","",( IFERROR(J12*BO12/INDEX(er!D:D, MATCH(Q12,er!C:C,0),1),0)))} -> 95.220441 | BR12: {=IFERROR(INDEX('Com&tax'!$F$2:$F$5, MATCH(1, ('Com&tax'!$A$2:$A$5=B12)*('Com&tax'!$D$2:$D$5=H12), 0)),0)} -> 0.049 | BS12: =IF(A12="","",( IFERROR((J12*(1-BE12))*BR12,0))) -> 79148.659 | BT12: {=IF(A12="","",( IFERROR((J12*(1-BE12))*BR12/INDEX(er!D:D, MATCH(Q12,er!C:C,0),1),0)))} -> 56.656163 | BU12: {=IFERROR(INDEX('Com&tax'!$G$2:$G$5, MATCH(1, ('Com&tax'!$A$2:$A$5=B12)*('Com&tax'!$D$2:$D$5=H12), 0)),0)} -> 0.1575 | BV12: =IF(A12="","",( IFERROR((J12*(1-BE12))*BU12,0))) -> 254406.4 | BW12: {=IF(A12="","",( IFERROR((J12*(1-BE12))*BU12/INDEX(er!D:D, MATCH(Q12,er!C:C,0),1),0)))} -> 182.10909 | BX12: {=IFERROR(INDEX('Com&tax'!$H$2:$H$5, MATCH(1, ('Com&tax'!$A$2:$A$5=B12)*('Com&tax'!$D$2:$D$5=H12), 0)),0)} -> 0.07 | BY12: =IF(A12="","",( IFERROR(J12*BX12,0))) -> 133022.96 | BZ12: {=IF(A12="","",( IFERROR(J12*BX12/INDEX(er!D:D, MATCH(Q12,er!C:C,0),1),0)))} -> 95.220441 | CA12: {=IF(A12="","",( IFERROR(1-((P12/ INDEX(er!$D$3:$D$75,MATCH(1, (er!$A$3:$A$75=$BG$2)*(er!$C$3:$C$75=Q12), 0)) / (J12/ INDEX(er!$D$3:$D$75,MATCH(1, (er!$A$3:$A$75=$BG$2)*(er!$C$3:$C$75=L12), 0))))),"")))} -> 0.39552496 | CB12: =IF(AB12="","",1-AD12/AB12) -> 0.395525 | CC12: =IF(AND(CA12="", CB12=""), "", CA12-CB12) -> -3.6835747e-08 | CD12: =BJ12+BM12-BS12-BV12 -> 0 | CE12: =BK12+BN12-BT12-BW12 -> 0 | CF12: =AJ12-CE12 -> 0 | CG12: =IF(OR(BE12="", AE12=""), "Miss", IF(ABS(AE12/100-AK12)<0.005, "OK", "Incorrect")) -> OK | CI12: OK | CK12: 0 | CL12: =(AI12+CK12)/INDEX(er!D:D,MATCH(AC12,er!C:C,0),1) -> 5.0107373e-05 | CN12: =CK12/INDEX(er!D:D,MATCH(AC12,er!C:C,0),1) -> 0
A13: T2993848 | B13: Twitter Rep | C13: IMS | D13: AR_Media Company_BALANZ CAPITAL VALORES Argentina_SMB-X ARG - Balanz - Enero 2025 | G13: Argentina | H13: Aleph Argentina | I13: Argentina | J13: 81926.99 | K13: 81926.99 | L13: ARS | M13: 81926.99 | N13: ARS | O13: 81926.99 | P13: 49522.82 | Q13: ARS | R13: Mexico | U13: 0 | V13: 2026-02 | W13: February/2026 | X13: IMS | Y13: Argentina | Z13: Mexico | AA13: ARS | AB13: 81926.99 | AC13: ARS | AD13: 49522.81 | AE13: 39.55 | AF13: OK | AG13: 0 | AH13: 0 | AI13: 0.01 | AJ13: 0 | AK13: 0.39552497 | AL13: OK | AM13: 10573656 | AO13: Miss | AP13: Miss | AR13: Miss | AT13: Miss | AU13: 81926.99 | AV13: 57 | AW13: Miss | AX13: 81926.99 | AY13: 58.64 | AZ13: ARS | BA13: 49522.81 | BB13: OK | BC13: 0.01 | BD13: 0 | BE13: {=IFERROR(INDEX('Com&tax'!$E$2:$E$5, MATCH(1, ('Com&tax'!$A$2:$A$5=B13)*('Com&tax'!$B$2:$B$5=G13), 0)),"")} -> 0.15 | BF13: =IF(A13="","",( IFERROR(O13*BE13,""))) -> 12289.049 | BG13: {=IF(A13="","",( IFERROR((O13/ INDEX(er!$D$3:$D$75,MATCH(1, (er!$A$3:$A$75=$BG$2)*(er!$C$3:$C$75=Q13), 0)))*BE13,"")))} -> 8.7967419 | BH13: =IF(A13="","",( IF(B13="Snapchat Rep", IF(A13="","",(P13-BF13)),-BF13))) -> -12289.049 | BI13: {=IFERROR(INDEX('Com&tax'!$F$2:$F$5, MATCH(1, ('Com&tax'!$A$2:$A$5=B13)*('Com&tax'!$B$2:$B$5=Y13), 0)),0)} -> 0.049 | BJ13: =IF(A13="","",( IFERROR((J13*(1-BE13))*BI13,0))) -> 3412.2591 | BK13: {=IF(A13="","",( IFERROR((J13*(1-BE13))*BI13/INDEX(er!D:D, MATCH(Q13,er!C:C,0),1),0)))} -> 2.442562 | BL13: {=IFERROR(INDEX('Com&tax'!$G$2:$G$5, MATCH(1, ('Com&tax'!$A$2:$A$5=B13)*('Com&tax'!$B$2:$B$5=Y13), 0)),0)} -> 0.1575 | BM13: =IF(A13="","",( IFERROR((J13*(1-BE13))*BL13,0))) -> 10967.976 | BN13: {=IF(A13="","",( IFERROR((J13*(1-BE13))*BL13/INDEX(er!D:D, MATCH(Q13,er!C:C,0),1),0)))} -> 7.8510922 | BO13: {=IFERROR(INDEX('Com&tax'!$H$2:$H$5, MATCH(1, ('Com&tax'!$A$2:$A$5=B13)*('Com&tax'!$B$2:$B$5=Y13), 0)),0)} -> 0.07 | BP13: =IF(A13="","",( IFERROR(J13*BO13,0))) -> 5734.8893 | BQ13: {=IF(A13="","",( IFERROR(J13*BO13/INDEX(er!D:D, MATCH(Q13,er!C:C,0),1),0)))} -> 4.1051462 | BR13: {=IFERROR(INDEX('Com&tax'!$F$2:$F$5, MATCH(1, ('Com&tax'!$A$2:$A$5=B13)*('Com&tax'!$D$2:$D$5=H13), 0)),0)} -> 0.049 | BS13: =IF(A13="","",( IFERROR((J13*(1-BE13))*BR13,0))) -> 3412.2591 | BT13: {=IF(A13="","",( IFERROR((J13*(1-BE13))*BR13/INDEX(er!D:D, MATCH(Q13,er!C:C,0),1),0)))} -> 2.442562 | BU13: {=IFERROR(INDEX('Com&tax'!$G$2:$G$5, MATCH(1, ('Com&tax'!$A$2:$A$5=B13)*('Com&tax'!$D$2:$D$5=H13), 0)),0)} -> 0.1575 | BV13: =IF(A13="","",( IFERROR((J13*(1-BE13))*BU13,0))) -> 10967.976 | BW13: {=IF(A13="","",( IFERROR((J13*(1-BE13))*BU13/INDEX(er!D:D, MATCH(Q13,er!C:C,0),1),0)))} -> 7.8510922 | BX13: {=IFERROR(INDEX('Com&tax'!$H$2:$H$5, MATCH(1, ('Com&tax'!$A$2:$A$5=B13)*('Com&tax'!$D$2:$D$5=H13), 0)),0)} -> 0.07 | BY13: =IF(A13="","",( IFERROR(J13*BX13,0))) -> 5734.8893 | BZ13: {=IF(A13="","",( IFERROR(J13*BX13/INDEX(er!D:D, MATCH(Q13,er!C:C,0),1),0)))} -> 4.1051462 | CA13: {=IF(A13="","",( IFERROR(1-((P13/ INDEX(er!$D$3:$D$75,MATCH(1, (er!$A$3:$A$75=$BG$2)*(er!$C$3:$C$75=Q13), 0)) / (J13/ INDEX(er!$D$3:$D$75,MATCH(1, (er!$A$3:$A$75=$BG$2)*(er!$C$3:$C$75=L13), 0))))),"")))} -> 0.39552497 | CB13: =IF(AB13="","",1-AD13/AB13) -> 0.39552509 | CC13: =IF(AND(CA13="", CB13=""), "", CA13-CB13) -> -1.220599e-07 | CD13: =BJ13+BM13-BS13-BV13 -> 0 | CE13: =BK13+BN13-BT13-BW13 -> 0 | CF13: =AJ13-CE13 -> 0 | CG13: =IF(OR(BE13="", AE13=""), "Miss", IF(ABS(AE13/100-AK13)<0.005, "OK", "Incorrect")) -> OK | CI13: OK | CK13: 0 | CL13: =(AI13+CK13)/INDEX(er!D:D,MATCH(AC13,er!C:C,0),1) -> 7.1581961e-06 | CN13: =CK13/INDEX(er!D:D,MATCH(AC13,er!C:C,0),1) -> 0
A14: T3025948 | B14: Twitter Billing | C14: IMS | D14: AR_Media Company_RAPPI ARG S.A.S._T3025948 - Rappi Argentina 2025 LInea de Credito - 19/02/2025 | G14: Argentina | H14: Aleph Argentina | I14: Argentina | J14: 16336338 | K14: 16336338 | L14: ARS | M14: 16336338 | N14: ARS | O14: 16336338 | P14: 10781901 | Q14: ARS | R14: Mexico | U14: 0 | V14: 2026-02 | W14: February/2026 | X14: IMS | Y14: Argentina | Z14: Mexico | AA14: ARS | AB14: 16336338 | AC14: ARS | AD14: 10782310 | AE14: 34 | AF14: OK | AG14: 0 | AH14: 0 | AI14: -408.41 | AJ14: -0.29 | AK14: 0.340005 | AL14: OK | AM14: 10573738 | AO14: Miss | AP14: Miss | AR14: Miss | AT14: Miss | AU14: 16336338 | AV14: 11692 | AW14: Miss | AX14: 16336338 | AY14: 11693.87 | AZ14: ARS | BA14: 10782310 | BB14: OK | BC14: -408.41 | BD14: -0.29 | BE14: {=IFERROR(INDEX('Com&tax'!$E$2:$E$5, MATCH(1, ('Com&tax'!$A$2:$A$5=B14)*('Com&tax'!$B$2:$B$5=G14), 0)),"")} -> 0.15 | BF14: =IF(A14="","",( IFERROR(O14*BE14,""))) -> 2450450.7 | BG14: {=IF(A14="","",( IFERROR((O14/ INDEX(er!$D$3:$D$75,MATCH(1, (er!$A$3:$A$75=$BG$2)*(er!$C$3:$C$75=Q14), 0)))*BE14,"")))} -> 1754.0807 | BH14: =IF(A14="","",( IF(B14="Snapchat Rep", IF(A14="","",(P14-BF14)),-BF14))) -> -2450450.7 | BI14: {=IFERROR(INDEX('Com&tax'!$F$2:$F$5, MATCH(1, ('Com&tax'!$A$2:$A$5=B14)*('Com&tax'!$B$2:$B$5=Y14), 0)),0)} -> 0.049 | BJ14: =IF(A14="","",( IFERROR((J14*(1-BE14))*BI14,0))) -> 680408.48 | BK14: {=IF(A14="","",( IFERROR((J14*(1-BE14))*BI14/INDEX(er!D:D, MATCH(Q14,er!C:C,0),1),0)))} -> 487.04973 | BL14: {=IFERROR(INDEX('Com&tax'!$G$2:$G$5, MATCH(1, ('Com&tax'!$A$2:$A$5=B14)*('Com&tax'!$B$2:$B$5=Y14), 0)),0)} -> 0.1575 | BM14: =IF(A14="","",( IFERROR((J14*(1-BE14))*BL14,0))) -> 2187027.2 | BN14: {=IF(A14="","",( IFERROR((J14*(1-BE14))*BL14/INDEX(er!D:D, MATCH(Q14,er!C:C,0),1),0)))} -> 1565.517 | BO14: {=IFERROR(INDEX('Com&tax'!$H$2:$H$5, MATCH(1, ('Com&tax'!$A$2:$A$5=B14)*('Com&tax'!$B$2:$B$5=Y14), 0)),0)} -> 0 | BP14: =IF(A14="","",( IFERROR(J14*BO14,0))) -> 0 | BQ14: {=IF(A14="","",( IFERROR(J14*BO14/INDEX(er!D:D, MATCH(Q14,er!C:C,0),1),0)))} -> 0 | BR14: {=IFERROR(INDEX('Com&tax'!$F$2:$F$5, MATCH(1, ('Com&tax'!$A$2:$A$5=B14)*('Com&tax'!$D$2:$D$5=H14), 0)),0)} -> 0.049 | BS14: =IF(A14="","",( IFERROR((J14*(1-BE14))*BR14,0))) -> 680408.48 | BT14: {=IF(A14="","",( IFERROR((J14*(1-BE14))*BR14/INDEX(er!D:D, MATCH(Q14,er!C:C,0),1),0)))} -> 487.04973 | BU14: {=IFERROR(INDEX('Com&tax'!$G$2:$G$5, MATCH(1, ('Com&tax'!$A$2:$A$5=B14)*('Com&tax'!$D$2:$D$5=H14), 0)),0)} -> 0.1575 | BV14: =IF(A14="","",( IFERROR((J14*(1-BE14))*BU14,0))) -> 2187027.2 | BW14: {=IF(A14="","",( IFERROR((J14*(1-BE14))*BU14/INDEX(er!D:D, MATCH(Q14,er!C:C,0),1),0)))} -> 1565.517 | BX14: {=IFERROR(INDEX('Com&tax'!$H$2:$H$5, MATCH(1, ('Com&tax'!$A$2:$A$5=B14)*('Com&tax'!$D$2:$D$5=H14), 0)),0)} -> 0 | BY14: =IF(A14="","",( IFERROR(J14*BX14,0))) -> 0 | BZ14: {=IF(A14="","",( IFERROR(J14*BX14/INDEX(er!D:D, MATCH(Q14,er!C:C,0),1),0)))} -> 0 | CA14: {=IF(A14="","",( IFERROR(1-((P14/ INDEX(er!$D$3:$D$75,MATCH(1, (er!$A$3:$A$75=$BG$2)*(er!$C$3:$C$75=Q14), 0)) / (J14/ INDEX(er!$D$3:$D$75,MATCH(1, (er!$A$3:$A$75=$BG$2)*(er!$C$3:$C$75=L14), 0))))),"")))} -> 0.340005 | CB14: =IF(AB14="","",1-AD14/AB14) -> 0.33998 | CC14: =IF(AND(CA14="", CB14=""), "", CA14-CB14) -> 2.5000095e-05 | CD14: =BJ14+BM14-BS14-BV14 -> 0 | CE14: =BK14+BN14-BT14-BW14 -> 0 | CF14: =AJ14-CE14 -> -0.29 | CG14: =IF(OR(BE14="", AE14=""), "Miss", IF(ABS(AE14/100-AK14)<0.005, "OK", "Incorrect")) -> OK | CI14: OK | CK14: 0 | CL14: =(AI14+CK14)/INDEX(er!D:D,MATCH(AC14,er!C:C,0),1) -> -0.29234789 | CN14: =CK14/INDEX(er!D:D,MATCH(AC14,er!C:C,0),1) -> 0
A15: T3094969 | B15: Twitter Rep | C15: IMS | D15: AR_Media Company_Industrial And Comercial Bank Of China - Argentina_X - YOY - Branding - Tácticos | G15: Argentina | H15: Aleph Argentina | I15: Argentina | J15: 610190.21 | K15: 610190.21 | L15: ARS | M15: 610190.21 | N15: ARS | O15: 610190.21 | P15: 368844.75 | Q15: ARS | R15: Mexico | U15: 0 | V15: 2026-02 | W15: February/2026 | X15: IMS | Y15: Argentina | Z15: Mexico | AA15: ARS | AB15: 610190.21 | AC15: ARS | AD15: 368844.72 | AE15: 39.55 | AF15: OK | AG15: 0 | AH15: 0 | AI15: 0.03 | AJ15: 0 | AK15: 0.39552496 | AL15: OK | AM15: 10573701 | AN15: Manually insert Revenue,Manually insert Cogs | AO15: Miss | AP15: Miss | AR15: Miss | AT15: Miss | AU15: 610190.21 | AV15: 435 | AW15: Miss | AX15: 610190.21 | AY15: 436.79 | AZ15: ARS | BA15: 368844.73 | BB15: OK | BC15: 0.02 | BD15: 0 | BE15: {=IFERROR(INDEX('Com&tax'!$E$2:$E$5, MATCH(1, ('Com&tax'!$A$2:$A$5=B15)*('Com&tax'!$B$2:$B$5=G15), 0)),"")} -> 0.15 | BF15: =IF(A15="","",( IFERROR(O15*BE15,""))) -> 91528.531 | BG15: {=IF(A15="","",( IFERROR((O15/ INDEX(er!$D$3:$D$75,MATCH(1, (er!$A$3:$A$75=$BG$2)*(er!$C$3:$C$75=Q15), 0)))*BE15,"")))} -> 65.517918 | BH15: =IF(A15="","",( IF(B15="Snapchat Rep", IF(A15="","",(P15-BF15)),-BF15))) -> -91528.531 | BI15: {=IFERROR(INDEX('Com&tax'!$F$2:$F$5, MATCH(1, ('Com&tax'!$A$2:$A$5=B15)*('Com&tax'!$B$2:$B$5=Y15), 0)),0)} -> 0.049 | BJ15: =IF(A15="","",( IFERROR((J15*(1-BE15))*BI15,0))) -> 25414.422 | BK15: {=IF(A15="","",( IFERROR((J15*(1-BE15))*BI15/INDEX(er!D:D, MATCH(Q15,er!C:C,0),1),0)))} -> 18.192142 | BL15: {=IFERROR(INDEX('Com&tax'!$G$2:$G$5, MATCH(1, ('Com&tax'!$A$2:$A$5=B15)*('Com&tax'!$B$2:$B$5=Y15), 0)),0)} -> 0.1575 | BM15: =IF(A15="","",( IFERROR((J15*(1-BE15))*BL15,0))) -> 81689.214 | BN15: {=IF(A15="","",( IFERROR((J15*(1-BE15))*BL15/INDEX(er!D:D, MATCH(Q15,er!C:C,0),1),0)))} -> 58.474742 | BO15: {=IFERROR(INDEX('Com&tax'!$H$2:$H$5, MATCH(1, ('Com&tax'!$A$2:$A$5=B15)*('Com&tax'!$B$2:$B$5=Y15), 0)),0)} -> 0.07 | BP15: =IF(A15="","",( IFERROR(J15*BO15,0))) -> 42713.315 | BQ15: {=IF(A15="","",( IFERROR(J15*BO15/INDEX(er!D:D, MATCH(Q15,er!C:C,0),1),0)))} -> 30.575028 | BR15: {=IFERROR(INDEX('Com&tax'!$F$2:$F$5, MATCH(1, ('Com&tax'!$A$2:$A$5=B15)*('Com&tax'!$D$2:$D$5=H15), 0)),0)} -> 0.049 | BS15: =IF(A15="","",( IFERROR((J15*(1-BE15))*BR15,0))) -> 25414.422 | BT15: {=IF(A15="","",( IFERROR((J15*(1-BE15))*BR15/INDEX(er!D:D, MATCH(Q15,er!C:C,0),1),0)))} -> 18.192142 | BU15: {=IFERROR(INDEX('Com&tax'!$G$2:$G$5, MATCH(1, ('Com&tax'!$A$2:$A$5=B15)*('Com&tax'!$D$2:$D$5=H15), 0)),0)} -> 0.1575 | BV15: =IF(A15="","",( IFERROR((J15*(1-BE15))*BU15,0))) -> 81689.214 | BW15: {=IF(A15="","",( IFERROR((J15*(1-BE15))*BU15/INDEX(er!D:D, MATCH(Q15,er!C:C,0),1),0)))} -> 58.474742 | BX15: {=IFERROR(INDEX('Com&tax'!$H$2:$H$5, MATCH(1, ('Com&tax'!$A$2:$A$5=B15)*('Com&tax'!$D$2:$D$5=H15), 0)),0)} -> 0.07 | BY15: =IF(A15="","",( IFERROR(J15*BX15,0))) -> 42713.315 | BZ15: {=IF(A15="","",( IFERROR(J15*BX15/INDEX(er!D:D, MATCH(Q15,er!C:C,0),1),0)))} -> 30.575028 | CA15: {=IF(A15="","",( IFERROR(1-((P15/ INDEX(er!$D$3:$D$75,MATCH(1, (er!$A$3:$A$75=$BG$2)*(er!$C$3:$C$75=Q15), 0)) / (J15/ INDEX(er!$D$3:$D$75,MATCH(1, (er!$A$3:$A$75=$BG$2)*(er!$C$3:$C$75=L15), 0))))),"")))} -> 0.39552496 | CB15: =IF(AB15="","",1-AD15/AB15) -> 0.39552501 | CC15: =IF(AND(CA15="", CB15=""), "", CA15-CB15) -> -4.9164997e-08 | CD15: =BJ15+BM15-BS15-BV15 -> 0 | CE15: =BK15+BN15-BT15-BW15 -> 0 | CF15: =AJ15-CE15 -> 0 | CG15: =IF(OR(BE15="", AE15=""), "Miss", IF(ABS(AE15/100-AK15)<0.005, "OK", "Incorrect")) -> OK | CI15: OK | CK15: 0 | CL15: =(AI15+CK15)/INDEX(er!D:D,MATCH(AC15,er!C:C,0),1) -> 2.1474588e-05 | CN15: =CK15/INDEX(er!D:D,MATCH(AC15,er!C:C,0),1) -> 0
A16: T3101174 | B16: Twitter Rep | C16: IMS | D16: AR_Media Company_Play Digital Argentina_TW - MODO - Promo Día | G16: Argentina | H16: Aleph Argentina | I16: Argentina | J16: 2007664.5 | K16: 2007664.5 | L16: ARS | M16: 2007664.5 | N16: ARS | O16: 2007664.5 | P16: 1213583.1 | Q16: ARS | R16: Mexico | U16: 0 | V16: 2026-02 | W16: February/2026 | X16: IMS | Y16: Argentina | Z16: Mexico | AA16: ARS | AB16: 2007664.5 | AC16: ARS | AD16: 1213583 | AE16: 39.55 | AF16: OK | AG16: 0 | AH16: 0 | AI16: 0.08 | AJ16: 0 | AK16: 0.39552496 | AL16: OK | AM16: 10573714 | AO16: Miss | AP16: Miss | AR16: Miss | AT16: Miss | AU16: 2007664.5 | AV16: 1435 | AW16: Miss | AX16: 2007664.5 | AY16: 1437.13 | AZ16: ARS | BA16: 1213583 | BB16: OK | BC16: 0.08 | BD16: 0 | BE16: {=IFERROR(INDEX('Com&tax'!$E$2:$E$5, MATCH(1, ('Com&tax'!$A$2:$A$5=B16)*('Com&tax'!$B$2:$B$5=G16), 0)),"")} -> 0.15 | BF16: =IF(A16="","",( IFERROR(O16*BE16,""))) -> 301149.67 | BG16: {=IF(A16="","",( IFERROR((O16/ INDEX(er!$D$3:$D$75,MATCH(1, (er!$A$3:$A$75=$BG$2)*(er!$C$3:$C$75=Q16), 0)))*BE16,"")))} -> 215.56884 | BH16: =IF(A16="","",( IF(B16="Snapchat Rep", IF(A16="","",(P16-BF16)),-BF16))) -> -301149.67 | BI16: {=IFERROR(INDEX('Com&tax'!$F$2:$F$5, MATCH(1, ('Com&tax'!$A$2:$A$5=B16)*('Com&tax'!$B$2:$B$5=Y16), 0)),0)} -> 0.049 | BJ16: =IF(A16="","",( IFERROR((J16*(1-BE16))*BI16,0))) -> 83619.226 | BK16: {=IF(A16="","",( IFERROR((J16*(1-BE16))*BI16/INDEX(er!D:D, MATCH(Q16,er!C:C,0),1),0)))} -> 59.856282 | BL16: {=IFERROR(INDEX('Com&tax'!$G$2:$G$5, MATCH(1, ('Com&tax'!$A$2:$A$5=B16)*('Com&tax'!$B$2:$B$5=Y16), 0)),0)} -> 0.1575 | BM16: =IF(A16="","",( IFERROR((J16*(1-BE16))*BL16,0))) -> 268776.08 | BN16: {=IF(A16="","",( IFERROR((J16*(1-BE16))*BL16/INDEX(er!D:D, MATCH(Q16,er!C:C,0),1),0)))} -> 192.39519 | BO16: {=IFERROR(INDEX('Com&tax'!$H$2:$H$5, MATCH(1, ('Com&tax'!$A$2:$A$5=B16)*('Com&tax'!$B$2:$B$5=Y16), 0)),0)} -> 0.07 | BP16: =IF(A16="","",( IFERROR(J16*BO16,0))) -> 140536.51 | BQ16: {=IF(A16="","",( IFERROR(J16*BO16/INDEX(er!D:D, MATCH(Q16,er!C:C,0),1),0)))} -> 100.59879 | BR16: {=IFERROR(INDEX('Com&tax'!$F$2:$F$5, MATCH(1, ('Com&tax'!$A$2:$A$5=B16)*('Com&tax'!$D$2:$D$5=H16), 0)),0)} -> 0.049 | BS16: =IF(A16="","",( IFERROR((J16*(1-BE16))*BR16,0))) -> 83619.226 | BT16: {=IF(A16="","",( IFERROR((J16*(1-BE16))*BR16/INDEX(er!D:D, MATCH(Q16,er!C:C,0),1),0)))} -> 59.856282 | BU16: {=IFERROR(INDEX('Com&tax'!$G$2:$G$5, MATCH(1, ('Com&tax'!$A$2:$A$5=B16)*('Com&tax'!$D$2:$D$5=H16), 0)),0)} -> 0.1575 | BV16: =IF(A16="","",( IFERROR((J16*(1-BE16))*BU16,0))) -> 268776.08 | BW16: {=IF(A16="","",( IFERROR((J16*(1-BE16))*BU16/INDEX(er!D:D, MATCH(Q16,er!C:C,0),1),0)))} -> 192.39519 | BX16: {=IFERROR(INDEX('Com&tax'!$H$2:$H$5, MATCH(1, ('Com&tax'!$A$2:$A$5=B16)*('Com&tax'!$D$2:$D$5=H16), 0)),0)} -> 0.07 | BY16: =IF(A16="","",( IFERROR(J16*BX16,0))) -> 140536.51 | BZ16: {=IF(A16="","",( IFERROR(J16*BX16/INDEX(er!D:D, MATCH(Q16,er!C:C,0),1),0)))} -> 100.59879 | CA16: {=IF(A16="","",( IFERROR(1-((P16/ INDEX(er!$D$3:$D$75,MATCH(1, (er!$A$3:$A$75=$BG$2)*(er!$C$3:$C$75=Q16), 0)) / (J16/ INDEX(er!$D$3:$D$75,MATCH(1, (er!$A$3:$A$75=$BG$2)*(er!$C$3:$C$75=L16), 0))))),"")))} -> 0.39552496 | CB16: =IF(AB16="","",1-AD16/AB16) -> 0.395525 | CC16: =IF(AND(CA16="", CB16=""), "", CA16-CB16) -> -3.9847296e-08 | CD16: =BJ16+BM16-BS16-BV16 -> 0 | CE16: =BK16+BN16-BT16-BW16 -> 0 | CF16: =AJ16-CE16 -> 0 | CG16: =IF(OR(BE16="", AE16=""), "Miss", IF(ABS(AE16/100-AK16)<0.005, "OK", "Incorrect")) -> OK | CI16: OK | CK16: 0 | CL16: =(AI16+CK16)/INDEX(er!D:D,MATCH(AC16,er!C:C,0),1) -> 5.7265569e-05 | CN16: =CK16/INDEX(er!D:D,MATCH(AC16,er!C:C,0),1) -> 0
A17: T3163143 | B17: Twitter Rep | C17: IMS | D17: AR_Media Company_Hipódromo Argentino de Palermo S.A_AR00380261-X-Betfun-Takeover-Q1 26 | G17: Argentina | H17: Aleph Argentina | I17: Argentina | J17: 3110400 | K17: 3110400 | L17: ARS | M17: 3110400 | N17: ARS | O17: 3110400 | P17: 1880159.2 | Q17: ARS | R17: Mexico | U17: 0 | V17: 2026-02 | W17: February/2026 | X17: IMS | Y17: Argentina | Z17: Mexico | AA17: ARS | AB17: 3110400 | AC17: ARS | AD17: 1880159 | AE17: 39.55 | AF17: OK | AG17: 0 | AH17: 0 | AI17: 0.12 | AJ17: 0 | AK17: 0.39552496 | AL17: OK | AM17: 10573720 | AO17: Miss | AP17: Miss | AR17: Miss | AT17: Miss | AU17: 3110400 | AV17: 2224 | AW17: Miss | AX17: 3110400 | AY17: 2226.49 | AZ17: ARS | BA17: 1880159 | BB17: OK | BC17: 0.12 | BD17: 0 | BE17: {=IFERROR(INDEX('Com&tax'!$E$2:$E$5, MATCH(1, ('Com&tax'!$A$2:$A$5=B17)*('Com&tax'!$B$2:$B$5=G17), 0)),"")} -> 0.15 | BF17: =IF(A17="","",( IFERROR(O17*BE17,""))) -> 466560 | BG17: {=IF(A17="","",( IFERROR((O17/ INDEX(er!$D$3:$D$75,MATCH(1, (er!$A$3:$A$75=$BG$2)*(er!$C$3:$C$75=Q17), 0)))*BE17,"")))} -> 333.9728 | BH17: =IF(A17="","",( IF(B17="Snapchat Rep", IF(A17="","",(P17-BF17)),-BF17))) -> -466560 | BI17: {=IFERROR(INDEX('Com&tax'!$F$2:$F$5, MATCH(1, ('Com&tax'!$A$2:$A$5=B17)*('Com&tax'!$B$2:$B$5=Y17), 0)),0)} -> 0.049 | BJ17: =IF(A17="","",( IFERROR((J17*(1-BE17))*BI17,0))) -> 129548.16 | BK17: {=IF(A17="","",( IFERROR((J17*(1-BE17))*BI17/INDEX(er!D:D, MATCH(Q17,er!C:C,0),1),0)))} -> 92.733114 | BL17: {=IFERROR(INDEX('Com&tax'!$G$2:$G$5, MATCH(1, ('Com&tax'!$A$2:$A$5=B17)*('Com&tax'!$B$2:$B$5=Y17), 0)),0)} -> 0.1575 | BM17: =IF(A17="","",( IFERROR((J17*(1-BE17))*BL17,0))) -> 416404.8 | BN17: {=IF(A17="","",( IFERROR((J17*(1-BE17))*BL17/INDEX(er!D:D, MATCH(Q17,er!C:C,0),1),0)))} -> 298.07072 | BO17: {=IFERROR(INDEX('Com&tax'!$H$2:$H$5, MATCH(1, ('Com&tax'!$A$2:$A$5=B17)*('Com&tax'!$B$2:$B$5=Y17), 0)),0)} -> 0.07 | BP17: =IF(A17="","",( IFERROR(J17*BO17,0))) -> 217728 | BQ17: {=IF(A17="","",( IFERROR(J17*BO17/INDEX(er!D:D, MATCH(Q17,er!C:C,0),1),0)))} -> 155.85397 | BR17: {=IFERROR(INDEX('Com&tax'!$F$2:$F$5, MATCH(1, ('Com&tax'!$A$2:$A$5=B17)*('Com&tax'!$D$2:$D$5=H17), 0)),0)} -> 0.049 | BS17: =IF(A17="","",( IFERROR((J17*(1-BE17))*BR17,0))) -> 129548.16 | BT17: {=IF(A17="","",( IFERROR((J17*(1-BE17))*BR17/INDEX(er!D:D, MATCH(Q17,er!C:C,0),1),0)))} -> 92.733114 | BU17: {=IFERROR(INDEX('Com&tax'!$G$2:$G$5, MATCH(1, ('Com&tax'!$A$2:$A$5=B17)*('Com&tax'!$D$2:$D$5=H17), 0)),0)} -> 0.1575 | BV17: =IF(A17="","",( IFERROR((J17*(1-BE17))*BU17,0))) -> 416404.8 | BW17: {=IF(A17="","",( IFERROR((J17*(1-BE17))*BU17/INDEX(er!D:D, MATCH(Q17,er!C:C,0),1),0)))} -> 298.07072 | BX17: {=IFERROR(INDEX('Com&tax'!$H$2:$H$5, MATCH(1, ('Com&tax'!$A$2:$A$5=B17)*('Com&tax'!$D$2:$D$5=H17), 0)),0)} -> 0.07 | BY17: =IF(A17="","",( IFERROR(J17*BX17,0))) -> 217728 | BZ17: {=IF(A17="","",( IFERROR(J17*BX17/INDEX(er!D:D, MATCH(Q17,er!C:C,0),1),0)))} -> 155.85397 | CA17: {=IF(A17="","",( IFERROR(1-((P17/ INDEX(er!$D$3:$D$75,MATCH(1, (er!$A$3:$A$75=$BG$2)*(er!$C$3:$C$75=Q17), 0)) / (J17/ INDEX(er!$D$3:$D$75,MATCH(1, (er!$A$3:$A$75=$BG$2)*(er!$C$3:$C$75=L17), 0))))),"")))} -> 0.39552496 | CB17: =IF(AB17="","",1-AD17/AB17) -> 0.395525 | CC17: =IF(AND(CA17="", CB17=""), "", CA17-CB17) -> -3.8580247e-08 | CD17: =BJ17+BM17-BS17-BV17 -> 0 | CE17: =BK17+BN17-BT17-BW17 -> 0 | CF17: =AJ17-CE17 -> 0 | CG17: =IF(OR(BE17="", AE17=""), "Miss", IF(ABS(AE17/100-AK17)<0.005, "OK", "Incorrect")) -> OK | CI17: OK | CK17: 0 | CL17: =(AI17+CK17)/INDEX(er!D:D,MATCH(AC17,er!C:C,0),1) -> 8.5898354e-05 | CN17: =CK17/INDEX(er!D:D,MATCH(AC17,er!C:C,0),1) -> 0
A18: T3163157 | B18: Twitter Rep | C18: IMS | D18: AR_Media Company_Hipódromo Argentino de Palermo S.A_AR00380263-X-Hipódromo Sala-Takeover-26 | G18: Argentina | H18: Aleph Argentina | I18: Argentina | J18: 3110400 | K18: 3110400 | L18: ARS | M18: 3110400 | N18: ARS | O18: 3110400 | P18: 1880159.2 | Q18: ARS | R18: Mexico | U18: 0 | V18: 2026-02 | W18: February/2026 | X18: IMS | Y18: Argentina | Z18: Mexico | AA18: ARS | AB18: 3110400 | AC18: ARS | AD18: 1880159 | AE18: 39.55 | AF18: OK | AG18: 0 | AH18: 0 | AI18: 0.12 | AJ18: 0 | AK18: 0.39552496 | AL18: OK | AM18: 10573735 | AO18: Miss | AP18: Miss | AR18: Miss | AT18: Miss | AU18: 3110400 | AV18: 2224 | AW18: Miss | AX18: 3110400 | AY18: 2226.49 | AZ18: ARS | BA18: 1880159 | BB18: OK | BC18: 0.12 | BD18: 0 | BE18: {=IFERROR(INDEX('Com&tax'!$E$2:$E$5, MATCH(1, ('Com&tax'!$A$2:$A$5=B18)*('Com&tax'!$B$2:$B$5=G18), 0)),"")} -> 0.15 | BF18: =IF(A18="","",( IFERROR(O18*BE18,""))) -> 466560 | BG18: {=IF(A18="","",( IFERROR((O18/ INDEX(er!$D$3:$D$75,MATCH(1, (er!$A$3:$A$75=$BG$2)*(er!$C$3:$C$75=Q18), 0)))*BE18,"")))} -> 333.9728 | BH18: =IF(A18="","",( IF(B18="Snapchat Rep", IF(A18="","",(P18-BF18)),-BF18))) -> -466560 | BI18: {=IFERROR(INDEX('Com&tax'!$F$2:$F$5, MATCH(1, ('Com&tax'!$A$2:$A$5=B18)*('Com&tax'!$B$2:$B$5=Y18), 0)),0)} -> 0.049 | BJ18: =IF(A18="","",( IFERROR((J18*(1-BE18))*BI18,0))) -> 129548.16 | BK18: {=IF(A18="","",( IFERROR((J18*(1-BE18))*BI18/INDEX(er!D:D, MATCH(Q18,er!C:C,0),1),0)))} -> 92.733114 | BL18: {=IFERROR(INDEX('Com&tax'!$G$2:$G$5, MATCH(1, ('Com&tax'!$A$2:$A$5=B18)*('Com&tax'!$B$2:$B$5=Y18), 0)),0)} -> 0.1575 | BM18: =IF(A18="","",( IFERROR((J18*(1-BE18))*BL18,0))) -> 416404.8 | BN18: {=IF(A18="","",( IFERROR((J18*(1-BE18))*BL18/INDEX(er!D:D, MATCH(Q18,er!C:C,0),1),0)))} -> 298.07072 | BO18: {=IFERROR(INDEX('Com&tax'!$H$2:$H$5, MATCH(1, ('Com&tax'!$A$2:$A$5=B18)*('Com&tax'!$B$2:$B$5=Y18), 0)),0)} -> 0.07 | BP18: =IF(A18="","",( IFERROR(J18*BO18,0))) -> 217728 | BQ18: {=IF(A18="","",( IFERROR(J18*BO18/INDEX(er!D:D, MATCH(Q18,er!C:C,0),1),0)))} -> 155.85397 | BR18: {=IFERROR(INDEX('Com&tax'!$F$2:$F$5, MATCH(1, ('Com&tax'!$A$2:$A$5=B18)*('Com&tax'!$D$2:$D$5=H18), 0)),0)} -> 0.049 | BS18: =IF(A18="","",( IFERROR((J18*(1-BE18))*BR18,0))) -> 129548.16 | BT18: {=IF(A18="","",( IFERROR((J18*(1-BE18))*BR18/INDEX(er!D:D, MATCH(Q18,er!C:C,0),1),0)))} -> 92.733114 | BU18: {=IFERROR(INDEX('Com&tax'!$G$2:$G$5, MATCH(1, ('Com&tax'!$A$2:$A$5=B18)*('Com&tax'!$D$2:$D$5=H18), 0)),0)} -> 0.1575 | BV18: =IF(A18="","",( IFERROR((J18*(1-BE18))*BU18,0))) -> 416404.8 | BW18: {=IF(A18="","",( IFERROR((J18*(1-BE18))*BU18/INDEX(er!D:D, MATCH(Q18,er!C:C,0),1),0)))} -> 298.07072 | BX18: {=IFERROR(INDEX('Com&tax'!$H$2:$H$5, MATCH(1, ('Com&tax'!$A$2:$A$5=B18)*('Com&tax'!$D$2:$D$5=H18), 0)),0)} -> 0.07 | BY18: =IF(A18="","",( IFERROR(J18*BX18,0))) -> 217728 | BZ18: {=IF(A18="","",( IFERROR(J18*BX18/INDEX(er!D:D, MATCH(Q18,er!C:C,0),1),0)))} -> 155.85397 | CA18: {=IF(A18="","",( IFERROR(1-((P18/ INDEX(er!$D$3:$D$75,MATCH(1, (er!$A$3:$A$75=$BG$2)*(er!$C$3:$C$75=Q18), 0)) / (J18/ INDEX(er!$D$3:$D$75,MATCH(1, (er!$A$3:$A$75=$BG$2)*(er!$C$3:$C$75=L18), 0))))),"")))} -> 0.39552496 | CB18: =IF(AB18="","",1-AD18/AB18) -> 0.395525 | CC18: =IF(AND(CA18="", CB18=""), "", CA18-CB18) -> -3.8580247e-08 | CD18: =BJ18+BM18-BS18-BV18 -> 0 | CE18: =BK18+BN18-BT18-BW18 -> 0 | CF18: =AJ18-CE18 -> 0 | CG18: =IF(OR(BE18="", AE18=""), "Miss", IF(ABS(AE18/100-AK18)<0.005, "OK", "Incorrect")) -> OK | CI18: OK | CK18: 0 | CL18: =(AI18+CK18)/INDEX(er!D:D,MATCH(AC18,er!C:C,0),1) -> 8.5898354e-05 | CN18: =CK18/INDEX(er!D:D,MATCH(AC18,er!C:C,0),1) -> 0
A19: T3163161 | B19: Twitter Billing | C19: IMS | D19: AR_Media Company_Mercado Libre Argentina_T3163161 - MLA | Double Dates 2026 | Takeovers - ORDEN N°1 | G19: Argentina | H19: Aleph Argentina | I19: Argentina | J19: 2304000 | K19: 2304000 | L19: ARS | M19: 2304000 | N19: ARS | O19: 2304000 | P19: 1520628.5 | Q19: ARS | R19: Mexico | U19: 0 | V19: 2026-02 | W19: February/2026 | X19: IMS | Y19: Argentina | Z19: Mexico | AA19: ARS | AB19: 2304000 | AC19: ARS | AD19: 1520686.1 | AE19: 34 | AF19: OK | AG19: 0 | AH19: 0 | AI19: -57.6 | AJ19: -0.04 | AK19: 0.340005 | AL19: OK | AM19: 10573724 | AO19: Miss | AP19: Miss | AR19: Miss | AT19: Miss | AU19: 2304000 | AV19: 1647 | AW19: Miss | AX19: 2304000 | AY19: 1649.25 | AZ19: ARS | BA19: 1520686.1 | BB19: OK | BC19: -57.6 | BD19: -0.04 | BE19: {=IFERROR(INDEX('Com&tax'!$E$2:$E$5, MATCH(1, ('Com&tax'!$A$2:$A$5=B19)*('Com&tax'!$B$2:$B$5=G19), 0)),"")} -> 0.15 | BF19: =IF(A19="","",( IFERROR(O19*BE19,""))) -> 345600 | BG19: {=IF(A19="","",( IFERROR((O19/ INDEX(er!$D$3:$D$75,MATCH(1, (er!$A$3:$A$75=$BG$2)*(er!$C$3:$C$75=Q19), 0)))*BE19,"")))} -> 247.38726 | BH19: =IF(A19="","",( IF(B19="Snapchat Rep", IF(A19="","",(P19-BF19)),-BF19))) -> -345600 | BI19: {=IFERROR(INDEX('Com&tax'!$F$2:$F$5, MATCH(1, ('Com&tax'!$A$2:$A$5=B19)*('Com&tax'!$B$2:$B$5=Y19), 0)),0)} -> 0.049 | BJ19: =IF(A19="","",( IFERROR((J19*(1-BE19))*BI19,0))) -> 95961.6 | BK19: {=IF(A19="","",( IFERROR((J19*(1-BE19))*BI19/INDEX(er!D:D, MATCH(Q19,er!C:C,0),1),0)))} -> 68.691195 | BL19: {=IFERROR(INDEX('Com&tax'!$G$2:$G$5, MATCH(1, ('Com&tax'!$A$2:$A$5=B19)*('Com&tax'!$B$2:$B$5=Y19), 0)),0)} -> 0.1575 | BM19: =IF(A19="","",( IFERROR((J19*(1-BE19))*BL19,0))) -> 308448 | BN19: {=IF(A19="","",( IFERROR((J19*(1-BE19))*BL19/INDEX(er!D:D, MATCH(Q19,er!C:C,0),1),0)))} -> 220.79313 | BO19: {=IFERROR(INDEX('Com&tax'!$H$2:$H$5, MATCH(1, ('Com&tax'!$A$2:$A$5=B19)*('Com&tax'!$B$2:$B$5=Y19), 0)),0)} -> 0 | BP19: =IF(A19="","",( IFERROR(J19*BO19,0))) -> 0 | BQ19: {=IF(A19="","",( IFERROR(J19*BO19/INDEX(er!D:D, MATCH(Q19,er!C:C,0),1),0)))} -> 0 | BR19: {=IFERROR(INDEX('Com&tax'!$F$2:$F$5, MATCH(1, ('Com&tax'!$A$2:$A$5=B19)*('Com&tax'!$D$2:$D$5=H19), 0)),0)} -> 0.049 | BS19: =IF(A19="","",( IFERROR((J19*(1-BE19))*BR19,0))) -> 95961.6 | BT19: {=IF(A19="","",( IFERROR((J19*(1-BE19))*BR19/INDEX(er!D:D, MATCH(Q19,er!C:C,0),1),0)))} -> 68.691195 | BU19: {=IFERROR(INDEX('Com&tax'!$G$2:$G$5, MATCH(1, ('Com&tax'!$A$2:$A$5=B19)*('Com&tax'!$D$2:$D$5=H19), 0)),0)} -> 0.1575 | BV19: =IF(A19="","",( IFERROR((J19*(1-BE19))*BU19,0))) -> 308448 | BW19: {=IF(A19="","",( IFERROR((J19*(1-BE19))*BU19/INDEX(er!D:D, MATCH(Q19,er!C:C,0),1),0)))} -> 220.79313 | BX19: {=IFERROR(INDEX('Com&tax'!$H$2:$H$5, MATCH(1, ('Com&tax'!$A$2:$A$5=B19)*('Com&tax'!$D$2:$D$5=H19), 0)),0)} -> 0 | BY19: =IF(A19="","",( IFERROR(J19*BX19,0))) -> 0 | BZ19: {=IF(A19="","",( IFERROR(J19*BX19/INDEX(er!D:D, MATCH(Q19,er!C:C,0),1),0)))} -> 0 | CA19: {=IF(A19="","",( IFERROR(1-((P19/ INDEX(er!$D$3:$D$75,MATCH(1, (er!$A$3:$A$75=$BG$2)*(er!$C$3:$C$75=Q19), 0)) / (J19/ INDEX(er!$D$3:$D$75,MATCH(1, (er!$A$3:$A$75=$BG$2)*(er!$C$3:$C$75=L19), 0))))),"")))} -> 0.340005 | CB19: =IF(AB19="","",1-AD19/AB19) -> 0.33998 | CC19: =IF(AND(CA19="", CB19=""), "", CA19-CB19) -> 2.5e-05 | CD19: =BJ19+BM19-BS19-BV19 -> 0 | CE19: =BK19+BN19-BT19-BW19 -> 0 | CF19: =AJ19-CE19 -> -0.04 | CG19: =IF(OR(BE19="", AE19=""), "Miss", IF(ABS(AE19/100-AK19)<0.005, "OK", "Incorrect")) -> OK | CI19: OK | CK19: 0 | CL19: =(AI19+CK19)/INDEX(er!D:D,MATCH(AC19,er!C:C,0),1) -> -0.04123121 | CN19: =CK19/INDEX(er!D:D,MATCH(AC19,er!C:C,0),1) -> 0
A20: T3184062 | B20: Twitter Rep | C20: IMS | D20: AR_Media Company_Play Digital Argentina_X | MODO | Promo Diarco | G20: Argentina | H20: Aleph Argentina | I20: Argentina | J20: 718276.95 | K20: 718276.95 | L20: ARS | M20: 718276.95 | N20: ARS | O20: 718276.95 | P20: 434180.49 | Q20: ARS | R20: Mexico | U20: 0 | V20: 2026-02 | W20: February/2026 | X20: IMS | Y20: Argentina | Z20: Mexico | AA20: ARS | AB20: 718276.95 | AC20: ARS | AD20: 434180.46 | AE20: 39.55 | AF20: OK | AG20: 0 | AH20: 0 | AI20: 0.03 | AJ20: 0 | AK20: 0.39552496 | AL20: OK | AM20: 10573725 | AO20: Miss | AP20: Miss | AR20: Miss | AT20: Miss | AU20: 718276.95 | AV20: 512 | AW20: Miss | AX20: 718276.95 | AY20: 514.16 | AZ20: ARS | BA20: 434180.46 | BB20: OK | BC20: 0.03 | BD20: 0 | BE20: {=IFERROR(INDEX('Com&tax'!$E$2:$E$5, MATCH(1, ('Com&tax'!$A$2:$A$5=B20)*('Com&tax'!$B$2:$B$5=G20), 0)),"")} -> 0.15 | BF20: =IF(A20="","",( IFERROR(O20*BE20,""))) -> 107741.54 | BG20: {=IF(A20="","",( IFERROR((O20/ INDEX(er!$D$3:$D$75,MATCH(1, (er!$A$3:$A$75=$BG$2)*(er!$C$3:$C$75=Q20), 0)))*BE20,"")))} -> 77.123509 | BH20: =IF(A20="","",( IF(B20="Snapchat Rep", IF(A20="","",(P20-BF20)),-BF20))) -> -107741.54 | BI20: {=IFERROR(INDEX('Com&tax'!$F$2:$F$5, MATCH(1, ('Com&tax'!$A$2:$A$5=B20)*('Com&tax'!$B$2:$B$5=Y20), 0)),0)} -> 0.049 | BJ20: =IF(A20="","",( IFERROR((J20*(1-BE20))*BI20,0))) -> 29916.235 | BK20: {=IF(A20="","",( IFERROR((J20*(1-BE20))*BI20/INDEX(er!D:D, MATCH(Q20,er!C:C,0),1),0)))} -> 21.414628 | BL20: {=IFERROR(INDEX('Com&tax'!$G$2:$G$5, MATCH(1, ('Com&tax'!$A$2:$A$5=B20)*('Com&tax'!$B$2:$B$5=Y20), 0)),0)} -> 0.1575 | BM20: =IF(A20="","",( IFERROR((J20*(1-BE20))*BL20,0))) -> 96159.327 | BN20: {=IF(A20="","",( IFERROR((J20*(1-BE20))*BL20/INDEX(er!D:D, MATCH(Q20,er!C:C,0),1),0)))} -> 68.832732 | BO20: {=IFERROR(INDEX('Com&tax'!$H$2:$H$5, MATCH(1, ('Com&tax'!$A$2:$A$5=B20)*('Com&tax'!$B$2:$B$5=Y20), 0)),0)} -> 0.07 | BP20: =IF(A20="","",( IFERROR(J20*BO20,0))) -> 50279.387 | BQ20: {=IF(A20="","",( IFERROR(J20*BO20/INDEX(er!D:D, MATCH(Q20,er!C:C,0),1),0)))} -> 35.990971 | BR20: {=IFERROR(INDEX('Com&tax'!$F$2:$F$5, MATCH(1, ('Com&tax'!$A$2:$A$5=B20)*('Com&tax'!$D$2:$D$5=H20), 0)),0)} -> 0.049 | BS20: =IF(A20="","",( IFERROR((J20*(1-BE20))*BR20,0))) -> 29916.235 | BT20: {=IF(A20="","",( IFERROR((J20*(1-BE20))*BR20/INDEX(er!D:D, MATCH(Q20,er!C:C,0),1),0)))} -> 21.414628 | BU20: {=IFERROR(INDEX('Com&tax'!$G$2:$G$5, MATCH(1, ('Com&tax'!$A$2:$A$5=B20)*('Com&tax'!$D$2:$D$5=H20), 0)),0)} -> 0.1575 | BV20: =IF(A20="","",( IFERROR((J20*(1-BE20))*BU20,0))) -> 96159.327 | BW20: {=IF(A20="","",( IFERROR((J20*(1-BE20))*BU20/INDEX(er!D:D, MATCH(Q20,er!C:C,0),1),0)))} -> 68.832732 | BX20: {=IFERROR(INDEX('Com&tax'!$H$2:$H$5, MATCH(1, ('Com&tax'!$A$2:$A$5=B20)*('Com&tax'!$D$2:$D$5=H20), 0)),0)} -> 0.07 | BY20: =IF(A20="","",( IFERROR(J20*BX20,0))) -> 50279.387 | BZ20: {=IF(A20="","",( IFERROR(J20*BX20/INDEX(er!D:D, MATCH(Q20,er!C:C,0),1),0)))} -> 35.990971 | CA20: {=IF(A20="","",( IFERROR(1-((P20/ INDEX(er!$D$3:$D$75,MATCH(1, (er!$A$3:$A$75=$BG$2)*(er!$C$3:$C$75=Q20), 0)) / (J20/ INDEX(er!$D$3:$D$75,MATCH(1, (er!$A$3:$A$75=$BG$2)*(er!$C$3:$C$75=L20), 0))))),"")))} -> 0.39552496 | CB20: =IF(AB20="","",1-AD20/AB20) -> 0.395525 | CC20: =IF(AND(CA20="", CB20=""), "", CA20-CB20) -> -4.1766619e-08 | CD20: =BJ20+BM20-BS20-BV20 -> 0 | CE20: =BK20+BN20-BT20-BW20 -> 0 | CF20: =AJ20-CE20 -> 0 | CG20: =IF(OR(BE20="", AE20=""), "Miss", IF(ABS(AE20/100-AK20)<0.005, "OK", "Incorrect")) -> OK | CI20: OK | CK20: 0 | CL20: =(AI20+CK20)/INDEX(er!D:D,MATCH(AC20,er!C:C,0),1) -> 2.1474588e-05 | CN20: =CK20/INDEX(er!D:D,MATCH(AC20,er!C:C,0),1) -> 0
